Workbook

Sheet Ruimtelijk programma
B2: Algemene ruimten | E2: =E6+E10+E28+E14+E23 -> 631.66
B3: Algemene ruimten (Automatisch berekend) | D3: BVO
C4: Verkeersruimten en technische installatieruimten | D4: =Vragenlijst!I5 -> 140.72
C5: Constructieopppervlakten | D5: =Vragenlijst!I6 -> 281.44
C6: Totaal | E6: =SUM(D4:D5) -> 422.16
B7: Centrale ruimten | D7: BVO
C8: =Vragenlijst!G11 -> Centrale ontmoetingsruimte incl. podium | D8: =Vragenlijst!I11 -> 78
C9: Bibliotheek | D9: =Vragenlijst!I14 -> 0
C10: Totaal | E10: =SUM(D8:D10) -> 78
B11: Werkplekken, vergaderen en pauzeren (medewerkers) | D11: BVO
C12: Kantoorruimten | D12: =Vragenlijst!I16 -> 24
C13: Teamruimte | D13: =Vragenlijst!I10 -> 24
C14: Totaal | E14: =SUM(D12:D14) -> 48
B15: Faciliteiten | D15: BVO
C16: Spreekruimten | D16: =Vragenlijst!I26 -> 36
C17: EHBO-/kolf-/rustruimte | D17: =Vragenlijst!I22 -> 8
C18: Creatieve- en techniekruimte | D18: =Vragenlijst!I15 -> 0
C19: Prikkelarme ruimten | D19: =Vragenlijst!I17 -> 8
C20: Zorg- en behandelruimte | D20: =Vragenlijst!I18 -> 0
C21: Was- en droogruimte | D21: =Vragenlijst!I19 -> 0
C22: Print- en kopieerruimte | D22: =Vragenlijst!I21 -> 6
C23: Totaal | E23: =SUM(D16:D22) -> 58
B24: Toiletten | D24: BVO
C25: Toiletten leerlingen | D25: =Vragenlijst!I23 -> 15
C26: Toiletten Personeel | D26: =Vragenlijst!I24 -> 2.5
C27: Toiletten openbaar | D27: =Vragenlijst!I25 -> 8
C28: Totaal | E28: =SUM(D25:D27) -> 25.5
B29: Onderwijszones | E29: =E34+E39+E44+E49 -> 590
B30: Geen cluster | C30: =IF(AND(C35="Cluster niet gekozen",C40="Cluster niet gekozen",C45="Cluster niet gekozen"),"Geen cluster gekozen","Clusters gekozen") -> Clusters gekozen | D30: BVO
C31: Theorielokaal | D31: =IF(C30="Clusters gekozen",0,Vragenlijst!E14*'Rekenmodel (achterkant)'!C19) -> 0
C32: Leerplein | D32: =IF(C30="Clusters gekozen",0,'Rekenmodel (achterkant)'!C49) -> 0
C33: Bergruimten | D33: =IF(C30="Clusters gekozen",0,'Rekenmodel (achterkant)'!J20) -> 0
C34: Totaal | E34: =SUM(D31:D33) -> 0
B35: Onderbouw | C35: =Vragenlijst!E15 -> Cluster gekozen | D35: BVO
C36: Theorielokaal | D36: =IF(C35="Cluster gekozen",Vragenlijst!D15*'Rekenmodel (achterkant)'!C19,0) -> 256
C37: Leerplein | D37: =IF(C35="Cluster gekozen",'Rekenmodel (achterkant)'!C49,0) -> 36
C38: Bergruimte | D38: =IF(C35="Cluster gekozen",'Rekenmodel (achterkant)'!J20/'Rekenmodel (achterkant)'!C45,0) -> 3
C39: Totaal | E39: =SUM(D36:D38) -> 295
B40: Middenbouw | C40: =Vragenlijst!E16 -> Cluster niet gekozen | D40: BVO
C41: Theorielokaal | D41: =IF(C40="Cluster gekozen",Vragenlijst!D16*'Rekenmodel (achterkant)'!C19,0) -> 0
...

Sheet Vragenlijst
G3: Ruimteverdeling | H3: BVO | I3: BVO
B4: Basisinformatie | C4: Hoeveel leerlingen heeft uw school? | D4: 240 | E4: ='Rekenmodel (achterkant)'!C7 -> 1407.2 | G4: Ruimtebudet | H4: ='Rekenmodel (achterkant)'!I4 -> 1407.2
C5: Wilt u het ruimtebudget overschrijven? | D5: Nee | G5: ='Rekenmodel (achterkant)'!H5 -> m² voor Verkeersruimten en technische installatieruimten | H5: ='Rekenmodel (achterkant)'!I5 -> 0.1 | I5: ='Rekenmodel (achterkant)'!J5 -> 140.72
C6: Welke onderwijsclusters zijn er? | D6: 2 clusters OB+BB | G6: ='Rekenmodel (achterkant)'!H6 -> m² voor Constructieoppervlakten | H6: ='Rekenmodel (achterkant)'!I6 -> 0.2 | I6: ='Rekenmodel (achterkant)'!J6 -> 281.44
C7: Hoeveel FTE heeft uw school? | D7: 12 | H7: -
G8: Over voor ruimtekeuzes/verdeling | H8: =H4-I5-I6 -> 985.04
B9: Lokalen | C9: Aantal lokalen o.b.v. leerlingaantal | D9: ='Rekenmodel (achterkant)'!C12 -> 8 | G9: Lokalen | I9: ='Rekenmodel (achterkant)'!J9 -> 512
C10: Hoe veel extra lokalen wilt u? | D10: 0 | G10: Teamkamer | I10: ='Rekenmodel (achterkant)'!J10 -> 24
C11: Totaal aantal lokalen | D11: ='Rekenmodel (achterkant)'!C14 -> 8 | G11: ='Rekenmodel (achterkant)'!H11 -> Centrale ontmoetingsruimte incl. podium | I11: ='Rekenmodel (achterkant)'!J11 -> 78
G12: ='Rekenmodel (achterkant)'!H12 -> Leerpleinen | I12: ='Rekenmodel (achterkant)'!J12 -> 88
B13: Lokalen verdeling | C13: Lokalen | D13: Berekening | E13: Verdeeld | G13: ='Rekenmodel (achterkant)'!H13 -> Speellokaal | I13: ='Rekenmodel (achterkant)'!J13 -> 90
C14: Totaal aantal lokalen | D14: ='Rekenmodel (achterkant)'!C14 -> 8 | E14: =IF(ISNUMBER(SEARCH("1",D6)),D14,SUM(D15:D17)) -> 8 | G14: ='Rekenmodel (achterkant)'!H14 -> Bibliotheek | I14: ='Rekenmodel (achterkant)'!J14 -> 0
C15: Aantal lokalen OB | D15: 4 | E15: =IF(ISNUMBER(SEARCH("OB",D6)),"Cluster gekozen","Cluster niet gekozen") -> Cluster gekozen | G15: ='Rekenmodel (achterkant)'!H15 -> Cretieve en techniekruimte | I15: ='Rekenmodel (achterkant)'!J15 -> 0
C16: Aantal lokalen MB | E16: =IF(ISNUMBER(SEARCH("MB",D6)),"Cluster gekozen","Cluster niet gekozen") -> Cluster niet gekozen | G16: ='Rekenmodel (achterkant)'!H16 -> Kantoorruimten | I16: ='Rekenmodel (achterkant)'!J16 -> 24
C17: Aantal lokalen BB | D17: 4 | E17: =IF(ISNUMBER(SEARCH("BB",D6)),"Cluster gekozen","Cluster niet gekozen") -> Cluster gekozen | G17: ='Rekenmodel (achterkant)'!H17 -> Prikkelarme ruimten | I17: ='Rekenmodel (achterkant)'!J17 -> 8
G18: ='Rekenmodel (achterkant)'!H18 -> Zorg- en behandelruimte | I18: ='Rekenmodel (achterkant)'!J18 -> 0
B19: Centrale ontmoetingsruimte | C19: Hoeveel klassen moeten tegelijk gebruik kunnen maken van de centrale ontmoetingsruimte? | D19: Hele cluster | G19: ='Rekenmodel (achterkant)'!H19 -> Was- en droogruimte | I19: ='Rekenmodel (achterkant)'!J19 -> 0
G20: ='Rekenmodel (achterkant)'!H20 -> Bergruimten | I20: ='Rekenmodel (achterkant)'!J20 -> 6
B21: Leerpleinen | C21: Hoeveel procent van het cluster moet tegelijk gebruik kunnnen maken van de leerpleinen? | D21: 0.3 | G21: ='Rekenmodel (achterkant)'!H21 -> Print- en kopieerruimte | I21: ='Rekenmodel (achterkant)'!J21 -> 6
G22: ='Rekenmodel (achterkant)'!H22 -> EHBO-/kolf-/rustruimte | I22: ='Rekenmodel (achterkant)'!J22 -> 8
B23: Speellokaal | C23: Heeft u recht op een speellokaal? (incl. berging, totaal 90m²) | D23: Ja | G23: ='Rekenmodel (achterkant)'!H23 -> Toiletten leerlingen | I23: ='Rekenmodel (achterkant)'!J23 -> 15
G24: ='Rekenmodel (achterkant)'!H24 -> Toiletten personeel | I24: ='Rekenmodel (achterkant)'!J24 -> 2.5
B25: Overige ruimten | G25: ='Rekenmodel (achterkant)'!H25 -> Toiletten openbaar | I25: ='Rekenmodel (achterkant)'!J25 -> 8
B26: Bilbliotheek | C26: Wilt u een bibliotheek | D26: Nee | G26: ='Rekenmodel (achterkant)'!H26 -> Spreekruimten | I26: ='Rekenmodel (achterkant)'!J26 -> 36
C27: Zo ja, hoeveel gebruikers moeten er tegelijk gebruik van de bibliotheek kunnen maken? | D27: Kwart klas | I27: +
B28: Creatief en techniek | C28: Wilt u een creatieve- en techniekruimte? (64m²) | D28: Nee | G28: ='Rekenmodel (achterkant)'!H28 -> Totale oppervlakte gemaakte keuzes | H28: ='Rekenmodel (achterkant)'!I28 -> 905.5
B29: Kantoorruimten | C29: Aantal kantoorruimten o.b.v. leerlingaantal | D29: ='Rekenmodel (achterkant)'!C71 -> 3 | G29: Oppervlakte te verdelen | I29: =H8-H28 -> 79.54 | J29: =IF(I29>0,"U kunt meer m² verdelen", IF(I29=0,"U heeft alle m² verdeeld", "Verdeel minder m²")) -> U kunt meer m² verdelen
C30: Wilt u het aantal kantoorruimten overschrijven? | D30: Nee
C31: Welk formaat kantoorruimten wilt u? | D31: Basis (8m²)
B32: Prikkelarme ruimten | C32: Hoeveel prikkelarme ruimten wilt u? | D32: 1
C33: Hoeveel kinderen moeten tegelijk gebruik kunnen maken van de prikkelarme ruimten? | D33: 8 m² (1-2 kinderen)
B34: Zorg- en behandelruimte | C34: Wilt u een zorg en behandelruimte? (12m²) | D34: Nee
B35: Was- en droogruimte | C35: Wilt u een was- en droogruimte? (6m²) | D35: Nee
B36: Bergruimten | C36: Welk formaat bergruimten wilt u? (1 per cluster) | D36: Basis (3m²)
B37: Print- en kopieerruimte | C37: Wilt u een Print- en kopieerruimte? (6m²) | D37: Ja
B38: EHBO-/kolf-/rustruimte | C38: Wilt u een EHBO-/kolf-/rustruimte? (8m²) | D38: Ja
B39: Spreekruimten | C39: Aantal spreekruimten o.b.v. leerlingaantal | D39: ='Rekenmodel (achterkant)'!C119 -> 3
C40: Wilt u het aantal spreekruimten overschrijven? | D40: Nee
C41: Welk formaat spreekruimten wilt u? | D41: Basis (12m²)

Sheet Rekenmodel (achterkant)
B3: Ruimtebudget | C3: Rekenwaarde | D3: Standaardwaarde | H3: Ruimteverdeling
B4: M² BVO per leerling | C4: 5.03 | D4: 5.03 | H4: Ruimtebudget | I4: ='Rekenmodel (achterkant)'!C8 -> 1407.2
B5: M² BVO vaste voet | C5: 200 | D5: 200 | H5: m² voor Verkeersruimten en technische installatieruimten | I5: =0.1 -> 0.1 | J5: =I5*I4 -> 140.72
B6: Aantal leerlingen | C6: =Vragenlijst!D4 -> 240 | H6: m² voor Constructieoppervlakten | I6: =0.2 -> 0.2 | J6: =I6*I4 -> 281.44
B7: Ruimtebudget o.b.v. leerlingaantal | C7: =IF(C6=0,0,C6*C4+C5) -> 1407.2
B8: Overschreven ruimtebudget | C8: =IF(C6=0,0,IF(Vragenlijst!D5="Ja",Vragenlijst!E5,C7)) -> 1407.2 | H8: Over voor ruimtekeuzes/verdeling | I8: =I4-J5-J6 -> 985.04
H9: Lokalen | J9: =IFERROR(C20,0) -> 512
B10: Aantal lokalen | C10: Rekenwaarde | D10: Standaardwaarde | H10: Teamkamer | J10: =IFERROR(C33,0) -> 24
B11: Aantal leerlingen per lokaal | C11: 30 | D11: 30 | H11: =IF(C40="Altijd inbegrepen","Centrale ontmoetingsruimte incl. podium","Centrale ontmoetingsruimte") -> Centrale ontmoetingsruimte incl. podium | J11: =IFERROR(C42,0) -> 78
B12: Aantal lokalen naar boven afgerond | C12: =ROUNDUP(C6/C11,0) -> 8 | H12: Leerpleinen | J12: =IFERROR(C50,0) -> 88
B13: Aantal gekozen extra lokalen | C13: =Vragenlijst!D10 -> 0 | H13: Speellokaal | J13: =IFERROR(IF(C58="Ja",C59,0),0) -> 90
B14: Totaal aantal lokalen | C14: =C13+C12 -> 8 | H14: Bibliotheek | J14: =IFERROR(IF(C62="Ja",C64,0),0) -> 0
H15: Cretieve en techniekruimte | J15: =IFERROR(IF(C67="Ja",C68,0),0) -> 0
B16: Lokaalgrootte | C16: Rekenwaarde | D16: Standaardwaarde | H16: Kantoorruimten | J16: =IFERROR(C76,) -> 24
B17: M² BVO per leerling | C17: 2 | D17: 2 | H17: Prikkelarme ruimten | J17: =IFERROR(C79*C81,) -> 8
B18: M² BVO voor docent | C18: 4 | D18: 4 | H18: Zorg- en behandelruimte | J18: =IFERROR(IF(C84="Ja",C85,0),0) -> 0
B19: Lokaalgrootte | C19: =C11*C17+C18 -> 64 | H19: Was- en droogruimte | J19: =IFERROR(IF(C88="Ja",C89,0),0) -> 0
B20: Totale oppervlakte lokalen | C20: =C19*C14 -> 512 | H20: Bergruimten | J20: =IFERROR(C93*C45,0) -> 6
H21: Print- en kopieerruimte | J21: =IFERROR(IF(C96="Ja",C97,0),0) -> 6
B22: Gekozen clustergroottes | C22: Rekenwaarde | H22: EHBO-/kolf-/rustruimte | J22: =IFERROR(IF(C100="Ja",C101,0),0) -> 8
B23: Gekozen clusterverdeling | C23: =Vragenlijst!D6 -> 2 clusters OB+BB | H23: Toiletten leerlingen | J23: =IFERROR(C108,) -> 15
B24: OB | C24: =Vragenlijst!D15 -> 4 | H24: Toiletten personeel | J24: =IFERROR(C113,0) -> 2.5
B25: MB | C25: =Vragenlijst!D16 -> 0 | H25: Toiletten openbaar | J25: =IFERROR(C116,0) -> 8
B26: BB | C26: =Vragenlijst!D17 -> 4 | H26: Spreekruimten | J26: =IFERROR(C123,0) -> 36
B27: Geen cluster | C27: =IF(C23="1 cluster",Vragenlijst!D14,0) -> 0 | J27: +
B28: Grootste cluster | C28: =MAX(C24:C27) -> 4 | H28: Totale oppervlakte gemaakte keuzes | I28: =SUM(J9:J26) -> 905.5
I29: ='Rekenmodel (achterkant)'!J29 -> 0
B30: Teamkamer | C30: Rekenwaarde | D30: Standaardwaarde | H30: Oppervlakte te verdelen | J30: =I8-I28 -> 79.54 | K30: =IF(J30>0,"U kunt meer m² verdelen", IF(J30=0,"U heeft alle m² verdeeld", "Verdeel minder m²")) -> U kunt meer m² verdelen
B31: Aantal BVO per FTE | C31: 2 | D31: 2
B32: Aantal FTE | C32: =Vragenlijst!D7 -> 12
B33: Totale oppervlakte teamkamer | C33: =C32*C31 -> 24
B35: Centrale ontmoetingsruimte | C35: Rekenwaarde | D35: Standaardwaarde
B36: Gekozen grootte | C36: =Vragenlijst!D19 -> Hele cluster
B37: M² BVO per gebruiker | C37: 0.5 | D37: 0.5
B38: Aantal gebruikers | C38: =IF(C36="Hele klas",C11+1, IF(C36="Hele cluster",(C28*C11)+C28, IF(C36="Hele school",C6+C32,""))) -> 124
B39: Oppervlakte centrale ontmoetingsruimte | C39: =IFERROR(C38*C37,0) -> 62
B40: Podium gekozen? | C40: Altijd inbegrepen
B41: Grootte podium | C41: 16 | D41: 16
B42: Totale grootte Centrale ontmoetingsruimte | C42: =IF(C40="Altijd inbegrepen",C41+C39,C39) -> 78
B44: leerpleinen | C44: Rekenwaarde
...

Sheet Dropdowns
B2: Ja Nee
C3: Ja
C4: Nee
B7: Onderwijsclusters
C8: 1 cluster
C9: 2 clusters OB+BB
C10: 3 clusters OB+MB+BB
B13: Aantallen
C14: 0
C15: 1
C16: 2
C17: 3
C18: 4
C19: 5
B22: Groepgrootte centrale ontmoetingsruimte
C23: Hele klas
C24: Hele cluster
C25: Hele school
B28: Groepgrootte Leerpleinen
C29: Halve klas
C30: Hele klas
C31: Twee klassen
B35: Bibliotheek
C36: Kwart klas
C37: Halve klas
C38: Hele klas
B41: Kantoor
C42: Basis (8m²)
C43: Groot (16m²)
B46: Prikkelarme ruimten
C47: 8 m² (1-2 kinderen)
C48: 16 m² (3-4 kinderen)
C49: 32 m² (4-8 kinderen)
B52: Bergruimten
C53: Basis (3m²)
C54: Middel (6m²)
C55: Groot (12m²)
B58: Keuken/Foodlab
C59: Kwart klas
C60: Halve klas
...
