Workbook

Sheet INPUT
D2: eenheid | E2: INVULLEN:
A3: SCENARIO 1 (alleen BVO is bekend) | C3: BVO | F3: <<ALTIJD INVULLEN
A5: OF
A7: SCENARIO 2 (meer hoeveelheden bekend) | C7: Bruto inhoud | D7: m3
C8: Bebouwd oppervlak | D8: m2
C9: Bruto gevel oppervlak | D9: m2
C10: Gevelopeningen | D10: m2
C11: Bruto dak oppervlak | D11: m2
C12: Dakopeningen | D12: m2
C13: Bruto binnenwandoppervlak | D13: m2
C14: Binnenwandopeningen | D14: m2
C15: Bruto terrein oppervlak | D15: m2
A18: KEUZES (VOOR BEIDE SCENARIO'S) | E18: KEUZE:
C19: Voldoen aan NEN9120 | E19: nee
C20: BBL, A, B of C | E20: BBL
C21: BENG, Frisse scholen Engergie klasse A,B of C, ENG of 0 op de meter | E21: BENG
C22: Aandeel biobased hergebruikt of gerecycled | E22: 15%
C23: Losmaakbaarheidsindex | E23: 30%
C24: Subbemetering | E24: nee
C25: Afvalwater hergebruiksysteem | E25: nee
C26: Grijswatersysteem | E26: nee
C27: Groendak | E27: nee
C28: Waterretentie systeem | E28: nee
C29: Extra beveiligingsmaatregelen | E29: nee
C30: Toegangscontrolesysteem | E30: nee
... C33: Slim gebouw | E33: nee
A36: VERDELING FUNCTIES | C36: School | E36: =Elementclusters!Q2 -> 1
C37: Kinderdagopvang | E37: 0
C38: Gymzaal | E38: 0
C39: Totaal (100%) | E39: =SUM(E36:E38) -> 1 | F39: =IF(E39<100%,"CONTROLEER INGEVULDE WAARDEN",IF(E39>100%,"CONTROLEER INGEVULDE WAARDEN",""))

Sheet Kenmerken
A1: Doelen en Uitgangspunten Generiek PvE | F1: POM
A2: Bovenliggend object naam | B2: Objectnaam | C2: Kenmerknaam | D2: Waarde | E2: Eenheid | F2: Parameter voor model? | G2: Zo ja welke fase? | H2: Hoe? | I2: Parameter Financieel | J2: Keuze velden | K2: Beoordelingskader | L2: Hoe | M2: Fase | N2: Wanneer
A3: Een betere school | B3: Kenmerken locatie | C3: Bouwhoogte | D3: 12 | E3: m | F3: Ja | G3: Gebied | H3: Uit Omgevingsplan of in te voeren | I3: nee | K3: Randvoorwaarde voor POM | L3: In ontwerpgeneratie | M3: gebouw
C4: Bebouwingspercentage | D4: 50 | E4: % | F4: ja | G4: Gebied | H4: Uit Omgevingsplan of in te voeren | I4: nee | K4: Randvoorwaarde voor POM | L4: In gebiedsuitgangspunten | M4: Gebied
C5: Eventuele ontheffingen/afwijkingen | D5: n.v.t. | F5: ja | G5: Gebied | H5: Uit Omgevingsplan of in te voeren | I5: nee | K5: Randvoorwaarde voor POM | L5: In gebiedsuitgangspunten | M5: Gebied
C6: Bijzondere aandachtspunten | D6: n.v.t. | F6: ja | G6: Gebied | H6: Uit Omgevingsplan of in te voeren | I6: nee | K6: Randvoorwaarde voor POM | L6: In gebiedsuitgangspunten | M6: Gebied
C7: Verkeerssituatie | D7: De verkeersontsluiting van het Integraal Kindcentrum is gericht op langzaam verkeer. De locatie is primair bereikbaar te voet en per fiets. Autoverkeer wordt zoveel mogelijk beperkt en gescheiden van loop- en fietsroutes van kinderen. De verkeerssituatie is ingericht op veilige breng- en haalmomenten binnen een woonomgeving. | F7: nee | I7: nee | K7: Handmatig door gebruiker | L7: Sliderkeuze 1-5 : 1 Voldoet helemaal niet 2Voldoet in grote mate niet 3 Voldoet in beperte mate 4 voldoet in grote mate 5 Voldoet voledig | M7: Afgewogen besluit
C8: Parkeren motorvoertuigen | D8: Parkeren voor motorvoertuigen is beperkt en functioneel van aard en bedoeld voor personeel, leveranciers en incidenteel bezoek. Parkeren vindt plaats op of nabij de kavel, passend binnen het stedenbouwkundig kader en geldende parkeernormen. Uitgangspunt is het voorkomen van verkeersonveiligheid en overlast voor de omgeving. | F8: ja | G8: Gebied | H8: In te tekenen | I8: nee | K8: Handmatig door gebruiker | L8: Sliderkeuze 1-5 | M8: Afgewogen besluit
C9: Stalling fietsen/scooters | D9: Voor leerlingen en medewerkers wordt voorzien in voldoende stallingsmogelijkheden voor fietsen en scooters. De stallingen zijn goed bereikbaar, overzichtelijk en veilig gesitueerd in relatie tot de entrees van het gebouw. Fietsstallingen vormen een integraal onderdeel van de verkeersafwikkeling rondom het IKC | F9: ja | G9: Gebied | H9: In te tekenen | I9: nee | K9: Handmatig door gebruiker | L9: Sliderkeuze 1-5 | M9: Afgewogen besluit
C10: Functies buitenruimte | D10: De buitenruimte maakt functioneel onderdeel uit van het Integraal Kindcentrum en is primair bedoeld voor gebruik door leerlingen van de basisschool en kinderen van de voorschoolse educatie. De buitenruimte wordt ingericht als speel- en verblijfsruimte die het onderwijs en de ontwikkeling van kinderen ondersteunt. De buitenruimte voor de voorschoolse educatie is afgebakend en niet openbaar toegankelijk. De buitenruimte van de basisschool is in principe niet publiek toegankelijk en wordt gebruikt tijdens schooltijden en onder toezicht. Buiten schooltijden kan medegebruik plaatsvinden indien dit organisatorisch en veilig kan worden ingericht. De buitenruimte is gericht op spelen, bewegen en verblijven en vormt een duidelijke overgang tussen gebouw en omgeving. | F10: ja | G10: Gebied | H10: In te tekenen | I10: nee | K10: Handmatig door gebruiker | L10: Sliderkeuze 1-5 | M10: Afgewogen besluit
B11: Wet- en regelgeving | C11: Wet- en regelgeving | D11: Het project moet voldoen aan alle relevante vigerende wet- en regelgeving (o.a. Bbl, Arbowetgeving), waaronder, maar niet beperkt tot, de wet- en regelgeving die genoemd wordt bij de gedefinieerde eisen. Bij verwijzingen naar externe normen (bijv. NEN -normen) moet worden uitgegaan van de meest recente versie en alle delen van de norm tenzij anders aangegeven. | F11: nee | I11: nee | K11: Niet
A12: Een functionele school | B12: Kenmerken school | C12: Aantal leerlingen | D12: 380 | E12: Leerlingen | F12: ja | G12: Start | H12: IN te voeren | I12: nee | K12: Randvoorwaarde voor POM | L12: In ontwerpgeneratie | M12: gebouw
C13: Aantal onderwijsmedewerkers | D13: 18 | E13: Docenten | F13: ja | G13: Start | H13: IN te voeren | I13: nee | K13: Randvoorwaarde voor POM | L13: In ontwerpgeneratie | M13: gebouw
C14: Aantal stafmedewerkers | D14: 4 | E14: Stafmedewerkers | F14: ja | G14: Start | H14: IN te voeren | I14: nee | K14: Randvoorwaarde voor POM | L14: In ontwerpgeneratie | M14: gebouw
C15: Onderwijstype | D15: Integraal Kindcentrum (IKC) met primair onderwijs en voorschoolse educatie. Binnen het gebouw is ruimte voor onderwijs aan kinderen van 4 tot 12 jaar en voorschoolse educatie voor kinderen van 2 tot 4 jaar. Eventueel medegebruik voor buitenschoolse opvang vindt plaats binnen de onderwijsruimten. | F15: nee | I15: nee | K15: Niet
C16: Identiteit/cultuur | D16: De school kenmerkt zich door een open en inclusieve cultuur, gericht op samenwerking, veiligheid en ontwikkeling. De huisvesting ondersteunt ontmoeting, overzicht en een prettige leer- en werkomgeving voor leerlingen en medewerkers. | F16: nee | I16: nee | K16: Niet
C17: Onderwijsvisie | D17: Het onderwijs is gericht op een evenwichtige ontwikkeling van kinderen, waarbij klassikale instructie wordt gecombineerd met zelfstandig werken en samenwerken. De leeromgeving faciliteert verschillende werkvormen en sluit aan bij de ontwikkelingsfase van leerlingen. | F17: nee | I17: nee | K17: Niet
C18: Missie | D18: De missie van de school is het bieden van kwalitatief goed primair onderwijs in een veilige en stimulerende omgeving, waarin leerlingen zich cognitief, sociaal en persoonlijk kunnen ontwikkelen. | F18: nee | I18: nee | K18: Niet
C19: Doelgroep | D19: De doelgroep bestaat uit kinderen van 2 tot 12 jaar uit de directe omgeving van de school. De school bedient een gemengde populatie leerlingen uit de wijk en biedt passend onderwijs binnen het reguliere primair onderwijs en voorschoolse educatie. | F19: nee | I19: nee | K19: Niet
C20: Structuur | D20: De school is georganiseerd volgens een onderbouw-, middenbouw- en bovenbouwstructuur, met een logische clustering van onderwijsruimten per bouw. Deze structuur ondersteunt overzicht, herkenbaarheid en efficiënt gebruik van ruimten. | F20: ja | G20: Start | H20: PvE-Tool | I20: nee | K20: Handmatig door gebruiker | L20: Sliderkeuze 1-5 | M20: Afgewogen besluit
C21: Aanvullende functies/gebruikers | D21: Naast het primair onderwijs en de voorschoolse educatie zijn er geen aanvullende externe gebouwgebruikers die beschikken over eigen, exclusieve ruimten binnen het gebouw. Eventuele buitenschoolse opvang en andere activiteiten maken gebruik van medegebruik van onderwijsruimten binnen vastgestelde tijden en afspraken. De gymzaal is een afzonderlijke functie en valt buiten het onderwijsdeel van het gebouw. | F21: ja | G21: Start | H21: PvE-Tool | I21: nee | K21: Handmatig door gebruiker | L21: Sliderkeuze 1-5 | M21: Afgewogen besluit
C22: Combinatiefuncties | D22: Buiten schooltijden kunnen de bestaande ruimten beperkt worden ingezet voor medegebruik, zoals buitenschoolse opvang en incidentele buurt- of wijkgerichte activiteiten. Dit betreft laagdrempelige activiteiten die passen binnen de onderwijsfunctie, zoals ontmoetingen, cursussen of kleinschalige bijeenkomsten. Het medegebruik vindt plaats binnen vastgestelde tijden en afspraken, zonder dat hiervoor aanvullende ruimten of aanpassingen aan het programma nodig zijn. | F22: nee | I22: nee | K22: Handmatig door gebruiker | L22: Sliderkeuze 1-5 | M22: Afgewogen besluit
B23: Huisvestingsconcept | C23: Huisvestingsconcept algemeen | D23: Het beoogde huisvestingsconcept is gericht op een functionele, overzichtelijke en flexibele leeromgeving die verschillende onderwijsactiviteiten ondersteunt. De huisvesting faciliteert zowel klassikale instructie als zelfstandig werken en samenwerken in kleinere groepen. Ruimten zijn zodanig georganiseerd dat ontmoeting en interactie tussen leerlingen en medewerkers mogelijk is, zonder dat dit ten koste gaat van rust en concentratie. De achterliggende doelstelling is het creëren van een toekomstbestendig gebouw dat meebeweegt met veranderende onderwijsbehoeften, efficiënt ruimtegebruik mogelijk maakt en bijdraagt aan een prettige en veilige leer- en werkomgeving voor alle gebruikers. | F23: nee | I23: nee | K23: Handmatig door gebruiker | L23: Sliderkeuze 1-5 | M23: Afgewogen besluit
C24: Ruimtelijke indeling | D24: De ruimtelijke indeling van het gebouw is gebaseerd op een heldere zonering en logische clustering van functies. Onderwijsruimten zijn geclusterd per bouw (onderbouw, middenbouw en bovenbouw), waardoor overzicht en herkenbaarheid voor leerlingen en medewerkers ontstaat. Ondersteunende functies en gedeelde voorzieningen zijn centraal gepositioneerd en goed bereikbaar vanuit de onderwijsclusters. De ruimten voor voorschoolse educatie vormen een eigen, duidelijk herkenbare zone binnen het gebouw, met een directe relatie met de buitenruimte. Functies met een mogelijk intensiever gebruik, zoals de gymzaal, zijn ruimtelijk zodanig gescheiden of gepositioneerd dat verstoring van het onderwijs wordt beperkt. | F24: Ja | G24: Start | H24: PvE-Tool | I24: nee | K24: Handmatig door gebruiker | L24: Sliderkeuze 1-5 | M24: Afgewogen besluit
C25: Logistiek | D25: De logistiek van het gebouw is gericht op overzicht en veiligheid. Er wordt uitgegaan van een duidelijke hoofdentree voor het primair onderwijs, met een logische en overzichtelijke routing naar de onderwijsruimten. Voor de voorschoolse educatie wordt voorzien in een eigen entree of een duidelijk gescheiden toegang, zodat verschillende gebruikersgroepen op een veilige en herkenbare wijze het gebouw kunnen betreden en verlaten. Bezoekers en medewerkers maken gebruik van de hoofdentree, waarbij interne routes zodanig zijn ingericht dat kruisende stromen zoveel mogelijk worden beperkt. Deze opzet draagt bij aan rust, veiligheid en efficiënt gebruik van het gebouw. | F25: nee | I25: nee | K25: Handmatig door gebruiker | L25: Sliderkeuze 1-5 | M25: Afgewogen besluit
C26: Gemeenschappelijke ruimtes | D26: Binnen het gebouw zijn enkele functies en ruimten bedoeld voor gedeeld gebruik door de verschillende gebouwgebruikers. Het betreft met name een centrale hal of ontmoetingsruimte die fungeert als entreegebied en informeel verblijfsgebied. Daarnaast kunnen ondersteunende ruimten, zoals een leer- of werkgebied, een kleine bibliotheekvoorziening of multifunctionele ruimte, flexibel worden ingezet door zowel onderwijs, voorschoolse educatie als eventueel medegebruik buiten schooltijden. Het gedeeld gebruik van deze ruimten draagt bij aan efficiënt ruimtegebruik en ontmoeting, zonder dat dit leidt tot extra ruimtevraag. | F26: nee | I26: nee | K26: Handmatig door gebruiker | L26: Sliderkeuze 1-5 | M26: Afgewogen besluit
C27: Typologie onderwijsruimten | D27: De onderwijsruimten zijn opgezet volgens een gedifferentieerde ruimtelijke typologie die aansluit op verschillende werkvormen en groepsgroottes. Uitgangspunt is een combinatie van overwegend gesloten groepsruimten voor klassikale instructie, aangevuld met aanvullende ruimten voor zelfstandig werken en samenwerken in kleinere groepen. De groepsruimten bieden plaats aan reguliere groepsgroottes en zijn zodanig van omvang dat flexibel gebruik mogelijk is. Aanvullende ruimten in de nabijheid van de groepsruimten ondersteunen differentiatie in het onderwijs, zoals werken in kleine groepen of individueel werken. De mate van open- en geslotenheid is afgestemd op een balans tussen rust, overzicht en interactie. De inrichting van de onderwijsruimten is flexibel en aanpasbaar, zodat verschillende onderwijsactiviteiten en toekomstige veranderingen in het onderwijsprogramma kunnen worden gefaciliteerd. | F27: ja | G27: Start | H27: PvE-Tool | I27: nee | K27: Handmatig door gebruiker | L27: Sliderkeuze 1-5 | M27: Afgewogen besluit
A28: Een aantrekkelijke school | B28: Uitstraling exterieur | C28: Beschrijving | D28: eigentijds en herkenbaar, passend binnen de schaal van de woonomgeving, uitnodigend en kindvriendelijk, overzichtelijk en transparant, duurzaam en toekomstbestendig, zorgvuldig ingepast in de omgeving | F28: nee | I28: nee | K28: Handmatig door gebruiker | L28: Sliderkeuze 1-5 | M28: Afgewogen besluit
B29: Uitstraling interieur | C29: Beschrijving | D29: licht en overzichtelijk, rustig en veilig, flexibel en aanpasbaar, warm en uitnodigend, functioneel en duurzaam, stimulerend voor leren en ontmoeten | F29: nee | I29: nee | K29: Niet
B30: Uitstraling buitenruimten | C30: Beschrijving | D30: groen en kindvriendelijk, veilig en overzichtelijk, uitnodigend tot spelen en bewegen, robuust en onderhoudsvriendelijk, passend bij de woonomgeving, functioneel en duurzaam | F30: nee | I30: nee | K30: Handmatig door gebruiker | L30: Sliderkeuze 1-5 | M30: Afgewogen besluit
A31: Een inclusieve school | B31: Een inclusieve school | C31: Relevante norm(en) | D31: NEN 9120 | F31: nee | I31: ja | J31: Voldoen aan NEN9120 JA of Nee | K31: Randvoorwaarde voor POM
B32: Ruimtelijke aspecten | C32: Navigatie ('wayfinding') | D32: Gebruikers moeten eenvoudig hun weg kunnen vinden binnen en buiten het gebouw, met een minimale noodzaak voor bewegwijzering. Denk aan natuurlijke looproutes, zichtlijnen en herkenningspunten. Bewegwijzering moet duidelijk zijn voor alle gebruikers, ongeacht leeftijd of fysieke mogelijkheden. | F32: nee | I32: nee | K32: Niet
C33: Hoogteverschillen | D33: Alle verdiepingen zelfstandig bereikbaar zijn voor alle gebruikers, ongeacht leeftijd of fysieke mogelijkheden. Op de verdiepingen zelf moeten hoogteverschillen en drempels vermeden worden. Waar hoogteverschillen niet te vermijden zijn, moet een vaste opstap, lift, trap en/of hellingbaan worden toegepast. | F33: nee | I33: nee
C34: Ruimte voor gebruik mobiliteitshulpmiddelen | D34: Het gebouw moet in verblijfsruimtes en de routes daar naartoe voorzien in voldoende ruimte voor het gebruik van mobiliteitshulpmiddelen. Denk aan doorgangsbreedtes, passeerruimte in gangen, draaicirkels bij trappen, manoeuvreerruimte bij deuren, en bedieningsruimte bij ramen, kasten, zonwering en andere bedienbare gebouwelementen. | F34: nee | I34: nee | K34: Automatisch door POM | L34: Toetsing van gangbreedtes en en draaijcirkels | M34: Gebouw
C35: Ruimten voor ondersteuning/behandeling | D35: Het gebouw moet voorzien in behandel- en/of spreekruimte(n) waar leerlingen kunnen afspreken met zorg- of ondersteuningspersoneel (bijv. maatschappelijk werkers, onderwijspsychologen, logopedisten). Kan gaan om specifieke ruimten, maar ook dubbel ruimtegebruik is mogelijk. Comfort, privacy en rust zijn belangrijke kwaliteiten. | F35: ja | G35: Start | H35: PvE-Tool | I35: nee | K35: Randvoorwaarde voor POM | L35: Ruimtes zijn onderdeel van de ruimtestaat | M35: Gebouw
C36: Ruimte voor opslag hulpmiddelen | D36: Het gebouw moet beschikken over opslagruimte voor hulpmiddelen die door leerlingen met een beperking worden gebruikt (bijv. rolstoelen, loophulpmiddelen, aangepaste stoelen en tafels, brailleleesapparatuur). Opslag moet gepositioneerd zijn in de directe omgeving van de onderwijsruimten waar de hulpmiddelen worden gebruikt. | F36: ja | G36: Start | H36: PvE-Tool | I36: nee | K36: Randvoorwaarde voor POM | L36: Ruimtes zijn onderdeel van de ruimtestaat | M36: Gebouw
C37: Diversiteit in plekken | D37: Voorzie in verschillende soorten ruimtes die aansluiten op uiteenlopende voorkeuren en behoeftes. Denk niet alleen aan klassieke onderwijsruimtes, maar ook stilteplekken voor geconcentreerd werken, groepsruimten voor samenwerking en informele leeromgevingen waar leerlingen zich op hun gemak voelen. | F37: ja | G37: Start | H37: PvE-Tool | I37: nee | K37: Randvoorwaarde voor POM | L37: Ruimtes zijn onderdeel van de ruimtestaat | M37: Gebouw
B38: Technische aspecten | C38: Binnenklimaat | D38: Sommige gebruikers zijn gevoeliger voor geluid, licht, temperatuur en allergenen dan anderen. Vanuit dit perspectief is het belangrijk dat binnenklimaat in de school beter is dan wettelijk minimum (zie DP-13). | F38: nee | I38: nee | K38: Niet
C39: Aanpasbaarheid | D39: Verblijfsruimtes moeten flexibel in te richten zijn om aan te sluiten op de diverse behoeften van gebruikers. Aandachtspunten zijn het kunnen aanpassen van de inrichting en de aanpasbaarheid van binnenklimaat (te openen ramen, aanpassen verlichting, aanpassen verwarming) | F39: nee | I39: nee | K39: Niet
C40: Aansluitingen hulpmiddelen | D40: In de school moeten voldoende en goed gepositioneerde aansluitingen beschikbaar zijn voor het opladen en gebruiken van hulpmiddelen door leerlingen en medewerkers met een beperking. Denk aan stroompunten voor het opladen van elektrische rolstoelen, gehoorversterkende apparatuur of andere hulpmiddelen. | F40: nee | I40: nee | K40: Niet
...

Sheet Sheet1
D1: Inclusieve school | E1: Toeslag op inbouwpakket | F1: Gezonde school | G1: Toeslag op W-installaties, Dak, Gevel, Inbouw | H1: Duurzame school | I1: Toeslag op alles | J1: Veilige school | K1: Toeslag op terrein, gevel en inbouw | L1: Digitale school | M1: Toeslag op E-installaties | N1: Bouwlocatie | O1: Toeslag op AUK | P1: Fundatie | Q1: Toeslag op fundering | R1: Aantal verdiepingen | S1: Toeslag | T1: Uitstraling (Architectuur) gevel | U1: Toeslag op gevel en constructie | V1: Uitstraling (Architectuur) binnen | W1: Toeslag op constructie en inbouw | X1: Exploitatieperiode
D2: Ja | E2: 0.01 | F2: Ja, maximaal | G2: 0.1 | H2: Ja, maximaal | I2: 0.2 | J2: Ja | K2: 0.02 | L2: Ja | M2: 0.02 | N2: Stad, goed bereikbaar | O2: 0 | P2: Fundering op palen | Q2: 0.05 | R2: 1 | T2: Sober en doelmatig | U2: -0.02 | V2: Sober en doelmatig | W2: -0.02 | X2: 25
D3: Nee | E3: 0 | F3: Ja, iets meer dan wettelijk vereist | G3: 0.05 | H3: Ja, iets meer dan wettelijk vereist | I3: 0.1 | J3: Nee | K3: 0 | L3: Nee | M3: 0 | N3: Stad, slecht bereikbaar | O3: 0.03 | P3: Fundering op staal | Q3: 0 | R3: 2 | T3: Gemiddeld | U3: 0 | V3: Gemiddeld | W3: 0 | X3: 30
F4: Nee | G4: 0 | H4: Nee | I4: 0 | N4: Dorp | O4: 0 | P4: Complexe omstandigheden | Q4: 0.1 | R4: 3 | T4: Hoogwaardige architectuur | U4: 0.1 | V4: Hoogwaardige architectuur | W4: 0.1 | X4: 40
N5: Eilanden | O5: 0.05 | R5: 4 | X5: 50
E14: heeft impact op exploitatie?
C15: Ja/nee | D15: Voldoen aan NEN9120 JA of Nee | E15: nee
C16: BBL, A, B of C | D16: BBL, A, B of C
C17: BENG, Frisse scholen Engergie klasse A,B of C, ENG of 0 op de meter | D17: BENG, Frisse scholen Engergie klasse A,B of C, ENG of 0 op de meter | E17: ja
C18: 15% 25% of 35% | D18: Aandeel biobased hergebruikt of gerecycled | E18: nee
C19: 30%, 40%, 50% | D19: Losmaakbaarheidsindex | E19: nee
C20: Ja/nee | D20: Subbemetering | E20: ja | F20: gemiddeld circa 8,5% besparing
C21: Ja/nee | D21: Afvalwater hergebruiksysteem | E21: ja | F21: gemiddeld circa 0,75 cent per jaar per BVO
C22: Ja/nee | D22: Grijswatersysteem | E22: ja
C23: Ja/nee | D23: Groendak | E23: ja
C24: Ja/nee | D24: Waterretentie systeem | E24: ja
C25: Ja/nee | D25: Extra beveiligingsmaatregelen | E25: ja
C26: Ja/nee | D26: Toegangscontrolesysteem | E26: ja
C27: Ja/nee | D27: Camerasysteem | E27: ja
C28: Ja/nee | D28: Vandaalbestendigheidsmaatregelen
C29: Ja/nee | D29: Slim gebouw | E29: ja

Sheet PO TCO
C1: Scenarios obv Kwaliteitskader 2026
C2: PO Klein 1312m2 | E2: PO Groot 2423m2
B3: BVO | C3: 1312 | D3: 1312 | E3: 2423 | F3: 2423
B4: NEN2699 | C4: Basis | D4: TCO | E4: Basis | F4: TCO
A5: 1 | B5: Bouwkundige werken | C5: 1211 | D5: 1267 | E5: 1071 | F5: 1122
A6: 2 | B6: Installatietechnische werken | C6: 573 | D6: 645 | E6: 527 | F6: 600
A7: 3 | B7: Vaste inrichting | C7: 45 | D7: 45 | E7: 36 | F7: 36
A8: 4 | B8: Terrein | C8: 88 | D8: 88 | E8: 95 | F8: 95
A9: 5 | B9: Indirecte bouwkosten | C9: 385 | D9: 411 | E9: 348 | F9: 373
A10: 6 | B10: Bouwkosten | C10: 2302 | D10: 2456 | E10: 2077 | F10: 2226
A11: 7 | B11: Bijkomende kosten | C11: 413 | D11: 441 | E11: 373 | F11: 400
A12: 8 | B12: Belasting | C12: 567 | D12: 605 | E12: 512 | F12: 549
A13: 9 | B13: Investeringskosten | C13: 3283 | D13: 3502 | E13: 2962 | F13: 3175
B16: Toeslagen
B17: Energie neutraal | C17: 143 | D17: 0 | E17: 138 | F17: 0
B18: Duurzaamheid | C18: 212 | D18: 212 | E18: 212 | F18: 212
B19: Frisse scholen | C19: 233 | D19: 233 | E19: 203 | F19: 203
B20: Exploitatie | C20: 24 | D20: 17 | E20: 20 | F20: 14
B21: ICT | C21: 5 | D21: 5 | E21: 5 | F21: 5
B22: Kwaliteit buitenruimte | C22: 96 | D22: 96 | E22: 100 | F22: 100
B23: Overig | C23: 113 | D23: 113 | E23: 83 | F23: 83
B24: Totaal aanvullend | C24: 826 | D24: 676 | E24: 762 | F24: 617
B27: Exploitatie (40 jaar)
B28: Heffingen | C28: 13 | D28: 14 | E28: 11 | F28: 12
B29: Verzekeringen | C29: 6 | D29: 6 | E29: 5 | F29: 5
B30: Onderhoud | C30: 54 | D30: 54 | E30: 47 | F30: 48
B31: Verbruik | C31: 13 | D31: 4 | E31: 13 | F31: 4
B32: Beheerskosten | C32: 0 | D32: 0 | E32: 0 | F32: 0
B33: Financieringskosten | C33: 0 | D33: 0 | E33: 0 | F33: 0
B34: Schoonmaakkosten | C34: 15 | D34: 14 | E34: 14 | F34: 14
B35: Totaal per m2 BVO/jaar | C35: 100 | D35: 93 | E35: 91 | F35: 84

Sheet Vormfactoren
A1: scenario 1 = ik krijg alleen BVO | D1: Indien alleen de BVO bekend is zal scenario 1 de vormfactoren bepalen.
A2: BVO | B2: =INPUT!E3 -> 0 | D2: Scenario 2 zal de vormfactoren, indien allen bekend, doorrekenen naar het TCO.
A4: Vormfactoren vlgs Cost Indicators | C4: Laag | D4: Top | E4: Hoog | F4: Perth | H4: resultaat waarmee gerekend wordt:
A5: Verdiepingshoogte | B5: BI / BVO (m¹) | C5: 2.9 | D5: 3.7 | E5: 4.4 | F5: =(C5+(4*D5)+E5)/6 -> 3.6833333 | H5: =F5 -> 3.6833333 | I5: BI / BVO (m¹)
A6: Aantal bouwlagen | B6: BVO / BBO (st) | C6: 1.7 | D6: 2.9 | E6: 8 | F6: =(C6+(4*D6)+E6)/6 -> 3.55 | H6: =F6 -> 3.55 | I6: BVO / BBO (st)
A7: Bebouwingspercentage | B7: BBO / BTO | C7: 0.4 | D7: 0.63 | E7: 0.95 | F7: =(C7+(4*D7)+E7)/6 -> 0.645 | H7: =F7 -> 0.645 | I7: BBO / BTO
A8: Gevelfactor | B8: BGO / BVO | C8: 0.32 | D8: 0.52 | E8: 0.82 | F8: =(C8+(4*D8)+E8)/6 -> 0.53666667 | H8: =F8 -> 0.53666667 | I8: BGO / BVO
A9: Gevelopeningen | B9: OG / BGO | C9: 0.25 | D9: 0.41 | E9: 0.76 | F9: =(C9+(4*D9)+E9)/6 -> 0.44166667 | H9: =F9 -> 0.44166667 | I9: OG / BGO
A10: Dakfactor | B10: BDO / BBO | C10: 1 | D10: 1.01 | E10: 1.13 | F10: =(C10+(4*D10)+E10)/6 -> 1.0283333 | H10: =F10 -> 1.0283333 | I10: BDO / BBO
A11: Dakopeningen | B11: OD / BDO | C11: 0 | D11: 0.05 | E11: 0.2 | F11: =(C11+(4*D11)+E11)/6 -> 0.066666667 | H11: =F11 -> 0.066666667 | I11: OD / BDO
A12: Binnenwandfactor | B12: BBWO / BVO | C12: 0.3 | D12: 0.66 | E12: 1 | F12: =(C12+(4*D12)+E12)/6 -> 0.65666667 | H12: =F12 -> 0.65666667 | I12: BBWO / BVO
A13: Binnenwandopeningen | B13: OBW / BBWO | C13: 0.06 | D13: 0.22 | E13: 0.85 | F13: =(C13+(4*D13)+E13)/6 -> 0.29833333 | H13: =F13 -> 0.29833333 | I13: OBW / BBWO
A14: Terreinoppervlak | B14: kavel / BVO | C14: 0.39 | D14: 0.54 | E14: 1.29 | F14: =(C14+(4*D14)+E14)/6 -> 0.64 | H14: =F14 -> 0.64 | I14: kavel / BVO
E16: Scenario 2:
A17: Afgeleide hoeveelheden in m2 | C17: M2 obv BVO factoren: | E17: Verkregen uit POM: | H17: resultaat waarmee gerekend wordt:
A18: Bruto inhoud | B18: BI | C18: =B2*H5 -> 0 | E18: =INPUT!E7 -> 0 | H18: =IF(E18>0,E18,C18) -> 0 | I18: BI
A19: Bebouwd oppervlak | B19: BBO | C19: =B2/H6 -> 0 | E19: =INPUT!E8 -> 0 | H19: =IF(E19>0,E19,C19) -> 0 | I19: BBO
A20: Bruto gevel oppervlak | B20: BGO | C20: =B2*H8 -> 0 | E20: =INPUT!E9 -> 0 | H20: =IF(E20>0,E20,C20) -> 0 | I20: BGO
A21: Gevelopeningen | B21: OG | C21: =C20*H9 -> 0 | E21: =INPUT!E10 -> 0 | H21: =IF(E21>0,E21,C21) -> 0 | I21: OG
A22: Bruto dak oppervlak | B22: BDO | C22: =C19*H10 -> 0 | E22: =INPUT!E11 -> 0 | H22: =IF(E22>0,E22,C22) -> 0 | I22: BDO
A23: Dakopeningen | B23: OD | C23: =C22*H11 -> 0 | E23: =INPUT!E12 -> 0 | H23: =IF(E23>0,E23,C23) -> 0 | I23: OD
A24: Bruto binnenwandoppervlak | B24: BBWO | C24: =B2*H12 -> 0 | E24: =INPUT!E13 -> 0 | H24: =IF(E24>0,E24,C24) -> 0 | I24: BBWO
A25: Binnenwandopeningen | B25: OBW | C25: =C24*H13 -> 0 | E25: =INPUT!E14 -> 0 | H25: =IF(E25>0,E25,C25) -> 0 | I25: OBW
A26: Bruto terrein oppervlak | B26: BTO | C26: =B2*H14 -> 0 | E26: =INPUT!E15 -> 0 | H26: =IF(E26>0,E26,C26) -> 0 | I26: BTO

Sheet keuzevelden
A1: nee | B1: BBL | C1: BENG | D1: 15% | E1: 30%
A2: ja | B2: A | C2: Frisse scholen Engergie klasse A | D2: 25% | E2: 40%
B3: B | C3: Frisse scholen Engergie klasse B | D3: 35% | E3: 50%
B4: C | C4: Frisse scholen Engergie klasse C
C5: ENG
C6: 0 op de meter

Sheet Elementclusters
B1: Bouwkosten | C1: Eenheid | M1: Totaal | P1: PO-School | S1: Gymzaal | V1: Kinderopvang | Y1: Functie 4 | AB1: Functie 5
B2: verhouding functies | Q2: =100%-T2-W2-Z2-AC2 -> 1 | T2: =INPUT!E38 -> 0 | W2: =INPUT!E37 -> 0 | Z2: =0% -> 0 | AC2: =0% -> 0 | AF2: Pro rata obv PO Scholen
B3: Basis | M3: Laag | N3: Top | O3: Hoog | P3: Laag | Q3: Top | R3: Hoog | S3: Laag | T3: Top | U3: Hoog | V3: Laag | W3: Top | X3: Hoog | Y3: Laag | Z3: Top | AA3: Hoog | AB3: Laag | AC3: Top | AD3: Hoog | AF3: Gymzaal | AI3: Kinderopvang | AL3: Functie 4 | AO3: Functie 5
B4: Slopen | C4: €/m² BVO | M4: =AVERAGE(P4*$Q$2+S4*$T$2+V4*$W$2+Y4*$Z$2+AB4*$AC$2) -> 0 | N4: =AVERAGE(Q4*$Q$2+T4*$T$2+W4*$W$2+Z4*$Z$2+AC4*$AC$2) -> 0 | O4: =AVERAGE(R4*$Q$2+U4*$T$2+X4*$W$2+AA4*$Z$2+AD4*$AC$2) -> 0 | P4: 0 | Q4: 0 | R4: 0 | S4: =P4*$AG$5 -> 0 | T4: =Q4*$AG$5 -> 0 | U4: =R4*$AG$5 -> 0 | V4: =P4*$AJ$5 -> 0 | W4: =Q4*$AJ$5 -> 0 | X4: =R4*$AJ$5 -> 0 | Y4: 0 | Z4: 0 | AA4: 0 | AB4: 0 | AC4: 0 | AD4: 0
B5: Onderbouw | C5: €/m² BBO | I5: 120 | J5: 195 | K5: 485 | M5: =AVERAGE(P5*$Q$2+S5*$T$2+V5*$W$2+Y5*$Z$2+AB5*$AC$2) -> 120 | N5: =AVERAGE(Q5*$Q$2+T5*$T$2+W5*$W$2+Z5*$Z$2+AC5*$AC$2) -> 185 | O5: =AVERAGE(R5*$Q$2+U5*$T$2+X5*$W$2+AA5*$Z$2+AD5*$AC$2) -> 485 | P5: 120 | Q5: 185 | R5: 485 | S5: =P5*$AG$5 -> 84 | T5: =Q5*$AG$5 -> 129.5 | U5: =R5*$AG$5 -> 339.5 | V5: =P5*$AJ$5 -> 138 | W5: =Q5*$AJ$5 -> 212.75 | X5: =R5*$AJ$5 -> 557.75 | Y5: 0 | Z5: 0 | AA5: 0 | AB5: 0 | AC5: 0 | AD5: 0 | AG5: 0.7 | AJ5: 1.15
B6: Bovenbouw | C6: €/m² BVO | I6: 145 | J6: 260 | K6: 345 | M6: =AVERAGE(P6*$Q$2+S6*$T$2+V6*$W$2+Y6*$Z$2+AB6*$AC$2) -> 145 | N6: =AVERAGE(Q6*$Q$2+T6*$T$2+W6*$W$2+Z6*$Z$2+AC6*$AC$2) -> 230 | O6: =AVERAGE(R6*$Q$2+U6*$T$2+X6*$W$2+AA6*$Z$2+AD6*$AC$2) -> 345 | P6: 145 | Q6: 230 | R6: 345 | S6: =P6*$AG$5 -> 101.5 | T6: =Q6*$AG$5 -> 161 | U6: =R6*$AG$5 -> 241.5 | V6: =P6*$AJ$5 -> 166.75 | W6: =Q6*$AJ$5 -> 264.5 | X6: =R6*$AJ$5 -> 396.75 | Y6: 0 | Z6: 0 | AA6: 0 | AB6: 0 | AC6: 0 | AD6: 0
B7: Gevel | C7: €/m² BGO | M7: =AVERAGE(P7*$Q$2+S7*$T$2+V7*$W$2+Y7*$Z$2+AB7*$AC$2) -> 240 | N7: =AVERAGE(Q7*$Q$2+T7*$T$2+W7*$W$2+Z7*$Z$2+AC7*$AC$2) -> 260 | O7: =AVERAGE(R7*$Q$2+U7*$T$2+X7*$W$2+AA7*$Z$2+AD7*$AC$2) -> 450 | P7: 240 | Q7: 260 | R7: 450 | S7: =P7*$AG$5 -> 168 | T7: =Q7*$AG$5 -> 182 | U7: =R7*$AG$5 -> 315 | V7: =P7*$AJ$5 -> 276 | W7: =Q7*$AJ$5 -> 299 | X7: =R7*$AJ$5 -> 517.5 | Y7: 0 | Z7: 0 | AA7: 0 | AB7: 0 | AC7: 0 | AD7: 0
B8: Gevel open (toeslag) | C8: €/m² OG | M8: =AVERAGE(P8*$Q$2+S8*$T$2+V8*$W$2+Y8*$Z$2+AB8*$AC$2) -> 150 | N8: =AVERAGE(Q8*$Q$2+T8*$T$2+W8*$W$2+Z8*$Z$2+AC8*$AC$2) -> 260 | O8: =AVERAGE(R8*$Q$2+U8*$T$2+X8*$W$2+AA8*$Z$2+AD8*$AC$2) -> 280 | P8: 150 | Q8: 260 | R8: 280 | S8: =P8*$AG$5 -> 105 | T8: =Q8*$AG$5 -> 182 | U8: =R8*$AG$5 -> 196 | V8: =P8*$AJ$5 -> 172.5 | W8: =Q8*$AJ$5 -> 299 | X8: =R8*$AJ$5 -> 322 | Y8: 0 | Z8: 0 | AA8: 0 | AB8: 0 | AC8: 0 | AD8: 0
B9: Dak | C9: €/m² BDO | M9: =AVERAGE(P9*$Q$2+S9*$T$2+V9*$W$2+Y9*$Z$2+AB9*$AC$2) -> 110.25 | N9: =AVERAGE(Q9*$Q$2+T9*$T$2+W9*$W$2+Z9*$Z$2+AC9*$AC$2) -> 145 | O9: =AVERAGE(R9*$Q$2+U9*$T$2+X9*$W$2+AA9*$Z$2+AD9*$AC$2) -> 241.5 | P9: =105*1.05 -> 110.25 | Q9: 145 | R9: =230*1.05 -> 241.5 | S9: =P9*$AG$5 -> 77.175 | T9: =Q9*$AG$5 -> 101.5 | U9: =R9*$AG$5 -> 169.05 | V9: =P9*$AJ$5 -> 126.7875 | W9: =Q9*$AJ$5 -> 166.75 | X9: =R9*$AJ$5 -> 277.725 | Y9: 0 | Z9: 0 | AA9: 0 | AB9: 0 | AC9: 0 | AD9: 0
B10: Inbouw | C10: €/m² BVO | M10: =AVERAGE(P10*$Q$2+S10*$T$2+V10*$W$2+Y10*$Z$2+AB10*$AC$2) -> 241.5 | N10: =AVERAGE(Q10*$Q$2+T10*$T$2+W10*$W$2+Z10*$Z$2+AC10*$AC$2) -> 315 | O10: =AVERAGE(R10*$Q$2+U10*$T$2+X10*$W$2+AA10*$Z$2+AD10*$AC$2) -> 456.75 | P10: =230*1.05 -> 241.5 | Q10: 315 | R10: =435*1.05 -> 456.75 | S10: =P10*$AG$5 -> 169.05 | T10: =Q10*$AG$5 -> 220.5 | U10: =R10*$AG$5 -> 319.725 | V10: =P10*$AJ$5 -> 277.725 | W10: =Q10*$AJ$5 -> 362.25 | X10: =R10*$AJ$5 -> 525.2625 | Y10: 0 | Z10: 0 | AA10: 0 | AB10: 0 | AC10: 0 | AD10: 0
B11: W-installaties | C11: €/m² BVO | M11: =AVERAGE(P11*$Q$2+S11*$T$2+V11*$W$2+Y11*$Z$2+AB11*$AC$2) -> 305 | N11: =AVERAGE(Q11*$Q$2+T11*$T$2+W11*$W$2+Z11*$Z$2+AC11*$AC$2) -> 325 | O11: =AVERAGE(R11*$Q$2+U11*$T$2+X11*$W$2+AA11*$Z$2+AD11*$AC$2) -> 420 | P11: 305 | Q11: 325 | R11: 420 | S11: =P11*$AG$5 -> 213.5 | T11: =Q11*$AG$5 -> 227.5 | U11: =R11*$AG$5 -> 294 | V11: =P11*$AJ$5 -> 350.75 | W11: =Q11*$AJ$5 -> 373.75 | X11: =R11*$AJ$5 -> 483 | Y11: 0 | Z11: 0 | AA11: 0 | AB11: 0 | AC11: 0 | AD11: 0
B12: E-installaties | C12: €/m² BVO | M12: =AVERAGE(P12*$Q$2+S12*$T$2+V12*$W$2+Y12*$Z$2+AB12*$AC$2) -> 150 | N12: =AVERAGE(Q12*$Q$2+T12*$T$2+W12*$W$2+Z12*$Z$2+AC12*$AC$2) -> 210 | O12: =AVERAGE(R12*$Q$2+U12*$T$2+X12*$W$2+AA12*$Z$2+AD12*$AC$2) -> 260 | P12: 150 | Q12: 210 | R12: 260 | S12: =P12*$AG$5 -> 105 | T12: =Q12*$AG$5 -> 147 | U12: =R12*$AG$5 -> 182 | V12: =P12*$AJ$5 -> 172.5 | W12: =Q12*$AJ$5 -> 241.5 | X12: =R12*$AJ$5 -> 299 | Y12: 0 | Z12: 0 | AA12: 0 | AB12: 0 | AC12: 0 | AD12: 0
B13: T-installaties | C13: €/m² BVO | M13: =AVERAGE(P13*$Q$2+S13*$T$2+V13*$W$2+Y13*$Z$2+AB13*$AC$2) -> 5.25 | N13: =AVERAGE(Q13*$Q$2+T13*$T$2+W13*$W$2+Z13*$Z$2+AC13*$AC$2) -> 21 | O13: =AVERAGE(R13*$Q$2+U13*$T$2+X13*$W$2+AA13*$Z$2+AD13*$AC$2) -> 63 | P13: =5*1.05 -> 5.25 | Q13: =20*1.05 -> 21 | R13: =60*1.05 -> 63 | S13: =P13*$AG$5 -> 3.675 | T13: =Q13*$AG$5 -> 14.7 | U13: =R13*$AG$5 -> 44.1 | V13: =P13*$AJ$5 -> 6.0375 | W13: =Q13*$AJ$5 -> 24.15 | X13: =R13*$AJ$5 -> 72.45 | Y13: 0 | Z13: 0 | AA13: 0 | AB13: 0 | AC13: 0 | AD13: 0
B14: Vaste inrichting | C14: €/m² BVO | M14: =AVERAGE(P14*$Q$2+S14*$T$2+V14*$W$2+Y14*$Z$2+AB14*$AC$2) -> 15.75 | N14: =AVERAGE(Q14*$Q$2+T14*$T$2+W14*$W$2+Z14*$Z$2+AC14*$AC$2) -> 21 | O14: =AVERAGE(R14*$Q$2+U14*$T$2+X14*$W$2+AA14*$Z$2+AD14*$AC$2) -> 57.75 | P14: =15*1.05 -> 15.75 | Q14: =20*1.05 -> 21 | R14: =55*1.05 -> 57.75 | S14: =P14*$AG$5 -> 11.025 | T14: =Q14*$AG$5 -> 14.7 | U14: =R14*$AG$5 -> 40.425 | V14: =P14*$AJ$5 -> 18.1125 | W14: =Q14*$AJ$5 -> 24.15 | X14: =R14*$AJ$5 -> 66.4125 | Y14: 0 | Z14: 0 | AA14: 0 | AB14: 0 | AC14: 0 | AD14: 0
B15: Terrein | C15: €/m² kavel | M15: =AVERAGE(P15*$Q$2+S15*$T$2+V15*$W$2+Y15*$Z$2+AB15*$AC$2) -> 36.75 | N15: =AVERAGE(Q15*$Q$2+T15*$T$2+W15*$W$2+Z15*$Z$2+AC15*$AC$2) -> 89.25 | O15: =AVERAGE(R15*$Q$2+U15*$T$2+X15*$W$2+AA15*$Z$2+AD15*$AC$2) -> 215.25 | P15: =35*1.05 -> 36.75 | Q15: =85*1.05 -> 89.25 | R15: =205*1.05 -> 215.25 | S15: =P15*$AG$5 -> 25.725 | T15: =Q15*$AG$5 -> 62.475 | U15: =R15*$AG$5 -> 150.675 | V15: =P15*$AJ$5 -> 42.2625 | W15: =Q15*$AJ$5 -> 102.6375 | X15: =R15*$AJ$5 -> 247.5375 | Y15: 0 | Z15: 0 | AA15: 0 | AB15: 0 | AC15: 0 | AD15: 0
B16: Subtotaal (directe bouwkosten) | M16: =AVERAGE(P16*$Q$2+S16*$T$2+V16*$W$2+Y16*$Z$2+AB16*$AC$2) -> 1491 | N16: =AVERAGE(Q16*$Q$2+T16*$T$2+W16*$W$2+Z16*$Z$2+AC16*$AC$2) -> 1653.75 | O16: =AVERAGE(R16*$Q$2+U16*$T$2+X16*$W$2+AA16*$Z$2+AD16*$AC$2) -> 2063.25 | P16: =1420*1.05 -> 1491 | Q16: =1575*1.05 -> 1653.75 | R16: =1965*1.05 -> 2063.25 | S16: =P16*$AG$5 -> 1043.7 | T16: =Q16*$AG$5 -> 1157.625 | U16: =R16*$AG$5 -> 1444.275 | V16: =P16*$AJ$5 -> 1714.65 | W16: =Q16*$AJ$5 -> 1901.8125 | X16: =R16*$AJ$5 -> 2372.7375 | Y16: 1 | Z16: 1 | AA16: 1 | AB16: 1 | AC16: 1 | AD16: 1
B17: AUK | M17: =AVERAGE(P17*$Q$2+S17*$T$2+V17*$W$2+Y17*$Z$2+AB17*$AC$2) -> 1.1 | N17: =AVERAGE(Q17*$Q$2+T17*$T$2+W17*$W$2+Z17*$Z$2+AC17*$AC$2) -> 1.1 | O17: =AVERAGE(R17*$Q$2+U17*$T$2+X17*$W$2+AA17*$Z$2+AD17*$AC$2) -> 1.1 | P17: 1.1 | Q17: 1.1 | R17: 1.1 | S17: =P17 -> 1.1 | T17: =S17 -> 1.1 | U17: =T17 -> 1.1 | V17: =S17 -> 1.1 | W17: =V17 -> 1.1 | X17: =W17 -> 1.1 | Y17: 0 | Z17: 0 | AA17: 0 | AB17: 0 | AC17: 0 | AD17: 0
B18: AK | M18: =AVERAGE(P18*$Q$2+S18*$T$2+V18*$W$2+Y18*$Z$2+AB18*$AC$2) -> 1.07 | N18: =AVERAGE(Q18*$Q$2+T18*$T$2+W18*$W$2+Z18*$Z$2+AC18*$AC$2) -> 1.07 | O18: =AVERAGE(R18*$Q$2+U18*$T$2+X18*$W$2+AA18*$Z$2+AD18*$AC$2) -> 1.07 | P18: 1.07 | Q18: 1.07 | R18: 1.07 | S18: 1.07 | T18: 1.07 | U18: 1.07 | V18: 1.07 | W18: 1.07 | X18: 1.07 | Y18: 0 | Z18: 0 | AA18: 0 | AB18: 0 | AC18: 0 | AD18: 0
B19: W&R | M19: =AVERAGE(P19*$Q$2+S19*$T$2+V19*$W$2+Y19*$Z$2+AB19*$AC$2) -> 1.03 | N19: =AVERAGE(Q19*$Q$2+T19*$T$2+W19*$W$2+Z19*$Z$2+AC19*$AC$2) -> 1.03 | O19: =AVERAGE(R19*$Q$2+U19*$T$2+X19*$W$2+AA19*$Z$2+AD19*$AC$2) -> 1.03 | P19: 1.03 | Q19: 1.03 | R19: 1.03 | S19: 1.04 | T19: 1.04 | U19: 1.04 | V19: 1.04 | W19: 1.04 | X19: 1.04 | Y19: 0 | Z19: 0 | AA19: 0 | AB19: 0 | AC19: 0 | AD19: 0
B20: Totale bouwkosten | M20: =AVERAGE(P20*$Q$2+S20*$T$2+V20*$W$2+Y20*$Z$2+AB20*$AC$2) -> 1737.75 | N20: =AVERAGE(Q20*$Q$2+T20*$T$2+W20*$W$2+Z20*$Z$2+AC20*$AC$2) -> 1937.25 | O20: =AVERAGE(R20*$Q$2+U20*$T$2+X20*$W$2+AA20*$Z$2+AD20*$AC$2) -> 2420.25 | P20: =1655*1.05 -> 1737.75 | Q20: =1845*1.05 -> 1937.25 | R20: =2305*1.05 -> 2420.25 | S20: =P20*$AG$5 -> 1216.425 | T20: =Q20*$AG$5 -> 1356.075 | U20: =R20*$AG$5 -> 1694.175 | V20: =P20*$AJ$5 -> 1998.4125 | W20: =Q20*$AJ$5 -> 2227.8375 | X20: =R20*$AJ$5 -> 2783.2875 | Y20: 0 | Z20: 0 | AA20: 0 | AB20: 0 | AC20: 0 | AD20: 0
B21: Totale bouwkosten incl. BTW | M21: =AVERAGE(P21*$Q$2+S21*$T$2+V21*$W$2+Y21*$Z$2+AB21*$AC$2) -> 2102.6775 | N21: =AVERAGE(Q21*$Q$2+T21*$T$2+W21*$W$2+Z21*$Z$2+AC21*$AC$2) -> 2344.0725 | O21: =AVERAGE(R21*$Q$2+U21*$T$2+X21*$W$2+AA21*$Z$2+AD21*$AC$2) -> 2928.5025 | P21: =P20*1.21 -> 2102.6775 | Q21: =Q20*1.21 -> 2344.0725 | R21: =R20*1.21 -> 2928.5025 | S21: =P21*$AG$5 -> 1471.8742 | T21: =Q21*$AG$5 -> 1640.8507 | U21: =R21*$AG$5 -> 2049.9517 | V21: =P21*$AJ$5 -> 2418.0791 | W21: =Q21*$AJ$5 -> 2695.6834 | X21: =R21*$AJ$5 -> 3367.7779 | Y21: 0 | Z21: 0 | AA21: 0 | AB21: 0 | AC21: 0 | AD21: 0
M22: Totaal | P22: PO-School | S22: Gymzaal | V22: Kinderopvang | Y22: Functie 4 | AB22: Functie 5
B23: LOSSE TOESLAGEN (DIRECTE KOSTEN + AUK + AK + W&R excl. BTW) | C23: Keuzes gebruiker: | D23: Optie: | E23: Impact op cluster: | F23: optie A | G23: optie B | H23: optie C | I23: optie D | J23: optie E | K23: optie F | L23: Factor Toeslag: | Q23: =Q2 -> 1 | T23: =T2 -> 0 | W23: =W2 -> 0 | Z23: =Z2 -> 0 | AC23: =AC2 -> 0
B24: Voldoen aan NEN9120 | C24: =INPUT!E19 -> nee | D24: =IF(ISTEXT(C24), IF(ISNUMBER(SEARCH("nee",UPPER($C24))),"Optie A", IF(ISNUMBER(SEARCH("ja",UPPER($C24))),"Optie B",""))) -> Optie A | E24: Inbouw, Terrein, Gevel | F24: 0 | G24: 1.025 | L24: =IF(D24="","",INDEX($F24:$K24,MATCH(D24,{"Optie A";"Optie B";"Optie C";"Optie D";"Optie E";"Optie F"},0))) -> 0 | M24: =MAX(0,((SUM(M10,M15,M7)*$L$24-SUM(M10,M15,M7))*((((($M$16*($M$17-1))+$M$16)*($M$18-1)+$M$16+($M$16*($M$17-1)))*($M$19-1)+$M$16+($M$16*($M$17-1))+(($M$16*($M$17-1))+$M$16)*($M$18-1))/$M$16))) -> 0 | N24: =MAX(0,((SUM(N10,N15,N7)*$L$24-SUM(N10,N15,N7))*((((($M$16*($M$17-1))+$M$16)*($M$18-1)+$M$16+($M$16*($M$17-1)))*($M$19-1)+$M$16+($M$16*($M$17-1))+(($M$16*($M$17-1))+$M$16)*($M$18-1))/$M$16))) -> 0 | O24: =MAX(0,((SUM(O10,O15,O7)*$L$24-SUM(O10,O15,O7))*((((($M$16*($M$17-1))+$M$16)*($M$18-1)+$M$16+($M$16*($M$17-1)))*($M$19-1)+$M$16+($M$16*($M$17-1))+(($M$16*($M$17-1))+$M$16)*($M$18-1))/$M$16))) -> 0 | P24: =MAX(0,((SUM(P10,P15,P7)*$L$24-SUM(P10,P15,P7))*((((($M$16*($M$17-1))+$M$16)*($M$18-1)+$M$16+($M$16*($M$17-1)))*($M$19-1)+$M$16+($M$16*($M$17-1))+(($M$16*($M$17-1))+$M$16)*($M$18-1))/$M$16))) -> 0 | Q24: =MAX(0,((SUM(Q10,Q15,Q7)*$L$24-SUM(Q10,Q15,Q7))*((((($M$16*($M$17-1))+$M$16)*($M$18-1)+$M$16+($M$16*($M$17-1)))*($M$19-1)+$M$16+($M$16*($M$17-1))+(($M$16*($M$17-1))+$M$16)*($M$18-1))/$M$16))) -> 0 | R24: =MAX(0,((SUM(R10,R15,R7)*$L$24-SUM(R10,R15,R7))*((((($M$16*($M$17-1))+$M$16)*($M$18-1)+$M$16+($M$16*($M$17-1)))*($M$19-1)+$M$16+($M$16*($M$17-1))+(($M$16*($M$17-1))+$M$16)*($M$18-1))/$M$16))) -> 0 | S24: =MAX(0,((SUM(S10,S15,S7)*$L$24-SUM(S10,S15,S7))*((((($M$16*($M$17-1))+$M$16)*($M$18-1)+$M$16+($M$16*($M$17-1)))*($M$19-1)+$M$16+($M$16*($M$17-1))+(($M$16*($M$17-1))+$M$16)*($M$18-1))/$M$16))) -> 0 | T24: =MAX(0,((SUM(T10,T15,T7)*$L$24-SUM(T10,T15,T7))*((((($M$16*($M$17-1))+$M$16)*($M$18-1)+$M$16+($M$16*($M$17-1)))*($M$19-1)+$M$16+($M$16*($M$17-1))+(($M$16*($M$17-1))+$M$16)*($M$18-1))/$M$16))) -> 0 | ... AD24: =MAX(0,((SUM(AD10,AD15,AD7)*$L$24-SUM(AD10,AD15,AD7))*((((($M$16*($M$17-1))+$M$16)*($M$18-1)+$M$16+($M$16*($M$17-1)))*($M$19-1)+$M$16+($M$16*($M$17-1))+(($M$16*($M$17-1))+$M$16)*($M$18-1))/$M$16))) -> 0
B25: BBL, A, B of C | C25: =INPUT!E20 -> BBL | D25: =IF(ISTEXT(C25), IF(ISNUMBER(SEARCH("BBL", UPPER($C25))), "Optie A", IF(ISNUMBER(SEARCH("A", UPPER($C25))), "Optie B", IF(ISNUMBER(SEARCH("B", UPPER($C25))), "Optie C", IF(ISNUMBER(SEARCH("C", UPPER($C25))), "Optie D", IF(ISNUMBER(SEARCH("OPTIE E", UPPER($C25))), "Optie E", IF(ISNUMBER(SEARCH("OPTIE F", UPPER($C25))), "Optie F", "")))))), "") -> Optie A | E25: Inbouw, Gevel, Dak, E-installatie, W-installaties | F25: 0 | G25: 1.045 | H25: 1.03 | I25: 1.015 | L25: =IF(D25="","",INDEX($F25:$K25,MATCH(D25,{"Optie A";"Optie B";"Optie C";"Optie D";"Optie E";"Optie F"},0))) -> 0 | M25: =MAX(0,((SUM(M10,M7,M9,M12,M11)*$L$25-SUM(M10,M7,M9,M12,M11))*(((((M16*(M17-1))+M16)*(M18-1)+M16+(M16*(M17-1)))*(M19-1)+M16+(M16*(M17-1))+((M16*(M17-1))+M16)*(M18-1))/M16))) -> 0 | N25: =MAX(0,((SUM(N10,N7,N9,N12,N11)*$L$25-SUM(N10,N7,N9,N12,N11))*(((((N16*(N17-1))+N16)*(N18-1)+N16+(N16*(N17-1)))*(N19-1)+N16+(N16*(N17-1))+((N16*(N17-1))+N16)*(N18-1))/N16))) -> 0 | O25: =MAX(0,((SUM(O10,O7,O9,O12,O11)*$L$25-SUM(O10,O7,O9,O12,O11))*(((((O16*(O17-1))+O16)*(O18-1)+O16+(O16*(O17-1)))*(O19-1)+O16+(O16*(O17-1))+((O16*(O17-1))+O16)*(O18-1))/O16))) -> 0 | P25: =MAX(0,((SUM(P10,P7,P9,P12,P11)*$L$25-SUM(P10,P7,P9,P12,P11))*(((((P16*(P17-1))+P16)*(P18-1)+P16+(P16*(P17-1)))*(P19-1)+P16+(P16*(P17-1))+((P16*(P17-1))+P16)*(P18-1))/P16))) -> 0 | Q25: =MAX(0,((SUM(Q10,Q7,Q9,Q12,Q11)*$L$25-SUM(Q10,Q7,Q9,Q12,Q11))*(((((Q16*(Q17-1))+Q16)*(Q18-1)+Q16+(Q16*(Q17-1)))*(Q19-1)+Q16+(Q16*(Q17-1))+((Q16*(Q17-1))+Q16)*(Q18-1))/Q16))) -> 0 | R25: =MAX(0,((SUM(R10,R7,R9,R12,R11)*$L$25-SUM(R10,R7,R9,R12,R11))*(((((R16*(R17-1))+R16)*(R18-1)+R16+(R16*(R17-1)))*(R19-1)+R16+(R16*(R17-1))+((R16*(R17-1))+R16)*(R18-1))/R16))) -> 0 | S25: =MAX(0,((SUM(S10,S7,S9,S12,S11)*$L$25-SUM(S10,S7,S9,S12,S11))*(((((S16*(S17-1))+S16)*(S18-1)+S16+(S16*(S17-1)))*(S19-1)+S16+(S16*(S17-1))+((S16*(S17-1))+S16)*(S18-1))/S16))) -> 0 | T25: =MAX(0,((SUM(T10,T7,T9,T12,T11)*$L$25-SUM(T10,T7,T9,T12,T11))*(((((T16*(T17-1))+T16)*(T18-1)+T16+(T16*(T17-1)))*(T19-1)+T16+(T16*(T17-1))+((T16*(T17-1))+T16)*(T18-1))/T16))) -> 0 | ... AD25: =MAX(0,((SUM(AD10,AD7,AD9,AD12,AD11)*$L$25-SUM(AD10,AD7,AD9,AD12,AD11))*(((((AD16*(AD17-1))+AD16)*(AD18-1)+AD16+(AD16*(AD17-1)))*(AD19-1)+AD16+(AD16*(AD17-1))+((AD16*(AD17-1))+AD16)*(AD18-1))/AD16))) -> 0
A26: x | B26: BENG, Frisse scholen Engergie klasse A,B of C, ENG of 0 op de meter | C26: =INPUT!E21 -> BENG | D26: =IF(ISTEXT(C26), IF(ISNUMBER(SEARCH("BENG", UPPER($C26))), "Optie A", IF(ISNUMBER(SEARCH("Frisse scholen Engergie klasse A", UPPER($C26))), "Optie B", IF(ISNUMBER(SEARCH("Frisse scholen Engergie klasse B", UPPER($C26))), "Optie C", IF(ISNUMBER(SEARCH("Frisse scholen Engergie klasse C", UPPER($C26))), "Optie D", IF(ISNUMBER(SEARCH("ENG", UPPER($C26))), "Optie E", IF(ISNUMBER(SEARCH("0 op de meter", UPPER($C26))), "Optie F", "")))))), "") -> Optie A | E26: Inbouw, Gevel, Dak, E-installatie, W-installaties | F26: 0 | G26: 1.12 | H26: 1.1 | I26: 1.05 | J26: 1.14 | K26: 1.15 | L26: =IF(D26="","",INDEX($F26:$K26,MATCH(D26,{"Optie A";"Optie B";"Optie C";"Optie D";"Optie E";"Optie F"},0))) -> 0 | M26: =MAX(0,((SUM(M10,M7,M9,M12,M11)*$L$26-SUM(M10,M7,M9,M12,M11))*(((((M16*(M17-1))+M16)*(M18-1)+M16+(M16*(M17-1)))*(M19-1)+M16+(M16*(M17-1))+((M16*(M17-1))+M16)*(M18-1))/M16))) -> 0 | N26: =MAX(0,((SUM(N10,N7,N9,N12,N11)*$L$26-SUM(N10,N7,N9,N12,N11))*(((((N16*(N17-1))+N16)*(N18-1)+N16+(N16*(N17-1)))*(N19-1)+N16+(N16*(N17-1))+((N16*(N17-1))+N16)*(N18-1))/N16))) -> 0 | O26: =MAX(0,((SUM(O10,O7,O9,O12,O11)*$L$26-SUM(O10,O7,O9,O12,O11))*(((((O16*(O17-1))+O16)*(O18-1)+O16+(O16*(O17-1)))*(O19-1)+O16+(O16*(O17-1))+((O16*(O17-1))+O16)*(O18-1))/O16))) -> 0 | P26: =MAX(0,((SUM(P10,P7,P9,P12,P11)*$L$26-SUM(P10,P7,P9,P12,P11))*(((((P16*(P17-1))+P16)*(P18-1)+P16+(P16*(P17-1)))*(P19-1)+P16+(P16*(P17-1))+((P16*(P17-1))+P16)*(P18-1))/P16))) -> 0 | Q26: =MAX(0,((SUM(Q10,Q7,Q9,Q12,Q11)*$L$26-SUM(Q10,Q7,Q9,Q12,Q11))*(((((Q16*(Q17-1))+Q16)*(Q18-1)+Q16+(Q16*(Q17-1)))*(Q19-1)+Q16+(Q16*(Q17-1))+((Q16*(Q17-1))+Q16)*(Q18-1))/Q16))) -> 0 | R26: =MAX(0,((SUM(R10,R7,R9,R12,R11)*$L$26-SUM(R10,R7,R9,R12,R11))*(((((R16*(R17-1))+R16)*(R18-1)+R16+(R16*(R17-1)))*(R19-1)+R16+(R16*(R17-1))+((R16*(R17-1))+R16)*(R18-1))/R16))) -> 0 | S26: =MAX(0,((SUM(S10,S7,S9,S12,S11)*$L$26-SUM(S10,S7,S9,S12,S11))*(((((S16*(S17-1))+S16)*(S18-1)+S16+(S16*(S17-1)))*(S19-1)+S16+(S16*(S17-1))+((S16*(S17-1))+S16)*(S18-1))/S16))) -> 0 | T26: =MAX(0,((SUM(T10,T7,T9,T12,T11)*$L$26-SUM(T10,T7,T9,T12,T11))*(((((T16*(T17-1))+T16)*(T18-1)+T16+(T16*(T17-1)))*(T19-1)+T16+(T16*(T17-1))+((T16*(T17-1))+T16)*(T18-1))/T16))) -> 0 | ... AD26: =MAX(0,((SUM(AD10,AD7,AD9,AD12,AD11)*$L$26-SUM(AD10,AD7,AD9,AD12,AD11))*(((((AD16*(AD17-1))+AD16)*(AD18-1)+AD16+(AD16*(AD17-1)))*(AD19-1)+AD16+(AD16*(AD17-1))+((AD16*(AD17-1))+AD16)*(AD18-1))/AD16))) -> 0
A27: x | B27: Aandeel biobased hergebruikt of gerecycled | C27: =INPUT!E22 -> 15% | D27: =IF(ISTEXT(C27), IF(ISNUMBER(SEARCH("15%", UPPER($C27))), "Optie A", IF(ISNUMBER(SEARCH("25%", UPPER($C27))), "Optie B", IF(ISNUMBER(SEARCH("35%", UPPER($C27))), "Optie C", IF(ISNUMBER(SEARCH("C", UPPER($C27))), "Optie D", IF(ISNUMBER(SEARCH("OPTIE E", UPPER($C27))), "Optie E", IF(ISNUMBER(SEARCH("OPTIE F", UPPER($C27))), "Optie F", "")))))), "") -> Optie A | E27: Bovenbouw, Gevel, Dak, Inbouw | F27: 1.01 | G27: 1.02 | H27: 1.03 | L27: =IF(D27="","",INDEX($F27:$K27,MATCH(D27,{"Optie A";"Optie B";"Optie C";"Optie D";"Optie E";"Optie F"},0))) -> 1.01 | M27: =MAX(0,((SUM(M6+M7+M9+M10)*$L$27-SUM(M6+M7+M9+M10))*(((((M16*(M17-1))+M16)*(M18-1)+M16+(M16*(M17-1)))*(M19-1)+M16+(M16*(M17-1))+((M16*(M17-1))+M16)*(M18-1))/M16))) -> 8.9316939 | N27: =MAX(0,((SUM(N6+N7+N9+N10)*$L$27-SUM(N6+N7+N9+N10))*(((((N16*(N17-1))+N16)*(N18-1)+N16+(N16*(N17-1)))*(N19-1)+N16+(N16*(N17-1))+((N16*(N17-1))+N16)*(N18-1))/N16))) -> 11.516945 | O27: =MAX(0,((SUM(O6+O7+O9+O10)*$L$27-SUM(O6+O7+O9+O10))*(((((O16*(O17-1))+O16)*(O18-1)+O16+(O16*(O17-1)))*(O19-1)+O16+(O16*(O17-1))+((O16*(O17-1))+O16)*(O18-1))/O16))) -> 18.102819 | P27: =MAX(0,((SUM(P6+P7+P9+P10)*$L$27-SUM(P6+P7+P9+P10))*(((((P16*(P17-1))+P16)*(P18-1)+P16+(P16*(P17-1)))*(P19-1)+P16+(P16*(P17-1))+((P16*(P17-1))+P16)*(P18-1))/P16))) -> 8.9316939 | Q27: =MAX(0,((SUM(Q6+Q7+Q9+Q10)*$L$27-SUM(Q6+Q7+Q9+Q10))*(((((Q16*(Q17-1))+Q16)*(Q18-1)+Q16+(Q16*(Q17-1)))*(Q19-1)+Q16+(Q16*(Q17-1))+((Q16*(Q17-1))+Q16)*(Q18-1))/Q16))) -> 11.516945 | R27: =MAX(0,((SUM(R6+R7+R9+R10)*$L$27-SUM(R6+R7+R9+R10))*(((((R16*(R17-1))+R16)*(R18-1)+R16+(R16*(R17-1)))*(R19-1)+R16+(R16*(R17-1))+((R16*(R17-1))+R16)*(R18-1))/R16))) -> 18.102819 | S27: =MAX(0,((SUM(S6+S7+S9+S10)*$L$27-SUM(S6+S7+S9+S10))*(((((S16*(S17-1))+S16)*(S18-1)+S16+(S16*(S17-1)))*(S19-1)+S16+(S16*(S17-1))+((S16*(S17-1))+S16)*(S18-1))/S16))) -> 6.3128866 | T27: =MAX(0,((SUM(T6+T7+T9+T10)*$L$27-SUM(T6+T7+T9+T10))*(((((T16*(T17-1))+T16)*(T18-1)+T16+(T16*(T17-1)))*(T19-1)+T16+(T16*(T17-1))+((T16*(T17-1))+T16)*(T18-1))/T16))) -> 8.140132 | ... AD27: =MAX(0,((SUM(AD6+AD7+AD9+AD10)*$L$27-SUM(AD6+AD7+AD9+AD10))*(((((AD16*(AD17-1))+AD16)*(AD18-1)+AD16+(AD16*(AD17-1)))*(AD19-1)+AD16+(AD16*(AD17-1))+((AD16*(AD17-1))+AD16)*(AD18-1))/AD16))) -> 0
A28: x | B28: Losmaakbaarheidsindex | C28: =INPUT!E23 -> 30% | D28: =IF(ISTEXT(C28), IF(ISNUMBER(SEARCH("30%", UPPER($C28))), "Optie A", IF(ISNUMBER(SEARCH("40%", UPPER($C28))), "Optie B", IF(ISNUMBER(SEARCH("50%", UPPER($C28))), "Optie C", IF(ISNUMBER(SEARCH("C", UPPER($C28))), "Optie D", IF(ISNUMBER(SEARCH("OPTIE E", UPPER($C28))), "Optie E", IF(ISNUMBER(SEARCH("OPTIE F", UPPER($C28))), "Optie F", "")))))), "") -> Optie A | E28: Bovenbouw, Gevel, Dak, Inbouw | F28: 1.015 | G28: 1.03 | H28: 1.045 | L28: =IF(D28="","",INDEX($F28:$K28,MATCH(D28,{"Optie A";"Optie B";"Optie C";"Optie D";"Optie E";"Optie F"},0))) -> 1.015 | M28: =MAX(0,((SUM(M6+M7+M10+M9)*$L$28-SUM(M6+M7+M10+M9))*(((((M16*(M17-1))+M16)*(M18-1)+M16+(M16*(M17-1)))*(M19-1)+M16+(M16*(M17-1))+((M16*(M17-1))+M16)*(M18-1))/M16))) -> 13.397541 | N28: =MAX(0,((SUM(N6+N7+N10+N9)*$L$28-SUM(N6+N7+N10+N9))*(((((N16*(N17-1))+N16)*(N18-1)+N16+(N16*(N17-1)))*(N19-1)+N16+(N16*(N17-1))+((N16*(N17-1))+N16)*(N18-1))/N16))) -> 17.275417 | O28: =MAX(0,((SUM(O6+O7+O10+O9)*$L$28-SUM(O6+O7+O10+O9))*(((((O16*(O17-1))+O16)*(O18-1)+O16+(O16*(O17-1)))*(O19-1)+O16+(O16*(O17-1))+((O16*(O17-1))+O16)*(O18-1))/O16))) -> 27.154229 | P28: =MAX(0,((SUM(P6+P7+P10+P9)*$L$28-SUM(P6+P7+P10+P9))*(((((P16*(P17-1))+P16)*(P18-1)+P16+(P16*(P17-1)))*(P19-1)+P16+(P16*(P17-1))+((P16*(P17-1))+P16)*(P18-1))/P16))) -> 13.397541 | Q28: =MAX(0,((SUM(Q6+Q7+Q10+Q9)*$L$28-SUM(Q6+Q7+Q10+Q9))*(((((Q16*(Q17-1))+Q16)*(Q18-1)+Q16+(Q16*(Q17-1)))*(Q19-1)+Q16+(Q16*(Q17-1))+((Q16*(Q17-1))+Q16)*(Q18-1))/Q16))) -> 17.275417 | R28: =MAX(0,((SUM(R6+R7+R10+R9)*$L$28-SUM(R6+R7+R10+R9))*(((((R16*(R17-1))+R16)*(R18-1)+R16+(R16*(R17-1)))*(R19-1)+R16+(R16*(R17-1))+((R16*(R17-1))+R16)*(R18-1))/R16))) -> 27.154229 | S28: =MAX(0,((SUM(S6+S7+S10+S9)*$L$28-SUM(S6+S7+S10+S9))*(((((S16*(S17-1))+S16)*(S18-1)+S16+(S16*(S17-1)))*(S19-1)+S16+(S16*(S17-1))+((S16*(S17-1))+S16)*(S18-1))/S16))) -> 9.4693299 | T28: =MAX(0,((SUM(T6+T7+T10+T9)*$L$28-SUM(T6+T7+T10+T9))*(((((T16*(T17-1))+T16)*(T18-1)+T16+(T16*(T17-1)))*(T19-1)+T16+(T16*(T17-1))+((T16*(T17-1))+T16)*(T18-1))/T16))) -> 12.210198 | ... AD28: =MAX(0,((SUM(AD6+AD7+AD10+AD9)*$L$28-SUM(AD6+AD7+AD10+AD9))*(((((AD16*(AD17-1))+AD16)*(AD18-1)+AD16+(AD16*(AD17-1)))*(AD19-1)+AD16+(AD16*(AD17-1))+((AD16*(AD17-1))+AD16)*(AD18-1))/AD16))) -> 0
B29: Subbemetering | C29: =INPUT!E24 -> nee | D29: =IF(ISTEXT(C29), IF(ISNUMBER(SEARCH("nee",UPPER($C29))),"Optie A", IF(ISNUMBER(SEARCH("ja",UPPER($C29))),"Optie B",""))) -> Optie A | E29: W-installaties | F29: 0 | G29: 1.05 | L29: =IF(D29="","",INDEX($F29:$K29,MATCH(D29,{"Optie A";"Optie B";"Optie C";"Optie D";"Optie E";"Optie F"},0))) -> 0 | M29: =MAX(0,((M11*$L$29-M11)*(((((M16*(M17-1))+M16)*(M18-1)+M16+(M16*(M17-1)))*(M19-1)+M16+(M16*(M17-1))+((M16*(M17-1))+M16)*(M18-1))/M16))) -> 0 | N29: =MAX(0,((N11*$L$29-N11)*(((((N16*(N17-1))+N16)*(N18-1)+N16+(N16*(N17-1)))*(N19-1)+N16+(N16*(N17-1))+((N16*(N17-1))+N16)*(N18-1))/N16))) -> 0 | O29: =MAX(0,((O11*$L$29-O11)*(((((O16*(O17-1))+O16)*(O18-1)+O16+(O16*(O17-1)))*(O19-1)+O16+(O16*(O17-1))+((O16*(O17-1))+O16)*(O18-1))/O16))) -> 0 | P29: =MAX(0,((P11*$L$29-P11)*(((((P16*(P17-1))+P16)*(P18-1)+P16+(P16*(P17-1)))*(P19-1)+P16+(P16*(P17-1))+((P16*(P17-1))+P16)*(P18-1))/P16))) -> 0 | Q29: =MAX(0,((Q11*$L$29-Q11)*(((((Q16*(Q17-1))+Q16)*(Q18-1)+Q16+(Q16*(Q17-1)))*(Q19-1)+Q16+(Q16*(Q17-1))+((Q16*(Q17-1))+Q16)*(Q18-1))/Q16))) -> 0 | R29: =MAX(0,((R11*$L$29-R11)*(((((R16*(R17-1))+R16)*(R18-1)+R16+(R16*(R17-1)))*(R19-1)+R16+(R16*(R17-1))+((R16*(R17-1))+R16)*(R18-1))/R16))) -> 0 | S29: =MAX(0,((S11*$L$29-S11)*(((((S16*(S17-1))+S16)*(S18-1)+S16+(S16*(S17-1)))*(S19-1)+S16+(S16*(S17-1))+((S16*(S17-1))+S16)*(S18-1))/S16))) -> 0 | T29: =MAX(0,((T11*$L$29-T11)*(((((T16*(T17-1))+T16)*(T18-1)+T16+(T16*(T17-1)))*(T19-1)+T16+(T16*(T17-1))+((T16*(T17-1))+T16)*(T18-1))/T16))) -> 0 | ... AD29: =MAX(0,((AD11*$L$29-AD11)*(((((AD16*(AD17-1))+AD16)*(AD18-1)+AD16+(AD16*(AD17-1)))*(AD19-1)+AD16+(AD16*(AD17-1))+((AD16*(AD17-1))+AD16)*(AD18-1))/AD16))) -> 0
B30: Afvalwater hergebruiksysteem | C30: =INPUT!E25 -> nee | D30: =IF(ISTEXT(C30), IF(ISNUMBER(SEARCH("nee",UPPER($C30))),"Optie A", IF(ISNUMBER(SEARCH("ja",UPPER($C30))),"Optie B",""))) -> Optie A | E30: W-installaties | F30: 0 | G30: 1.05 | L30: =IF(D30="","",INDEX($F30:$K30,MATCH(D30,{"Optie A";"Optie B";"Optie C";"Optie D";"Optie E";"Optie F"},0))) -> 0 | M30: =MAX(0,((M11*$L$30-M11)*(((((M16*(M17-1))+M16)*(M18-1)+M16+(M16*(M17-1)))*(M19-1)+M16+(M16*(M17-1))+((M16*(M17-1))+M16)*(M18-1))/M16))) -> 0 | N30: =MAX(0,((N11*$L$30-N11)*(((((N16*(N17-1))+N16)*(N18-1)+N16+(N16*(N17-1)))*(N19-1)+N16+(N16*(N17-1))+((N16*(N17-1))+N16)*(N18-1))/N16))) -> 0 | O30: =MAX(0,((O11*$L$30-O11)*(((((O16*(O17-1))+O16)*(O18-1)+O16+(O16*(O17-1)))*(O19-1)+O16+(O16*(O17-1))+((O16*(O17-1))+O16)*(O18-1))/O16))) -> 0 | P30: =MAX(0,((P11*$L$30-P11)*(((((P16*(P17-1))+P16)*(P18-1)+P16+(P16*(P17-1)))*(P19-1)+P16+(P16*(P17-1))+((P16*(P17-1))+P16)*(P18-1))/P16))) -> 0 | Q30: =MAX(0,((Q11*$L$30-Q11)*(((((Q16*(Q17-1))+Q16)*(Q18-1)+Q16+(Q16*(Q17-1)))*(Q19-1)+Q16+(Q16*(Q17-1))+((Q16*(Q17-1))+Q16)*(Q18-1))/Q16))) -> 0 | R30: =MAX(0,((R11*$L$30-R11)*(((((R16*(R17-1))+R16)*(R18-1)+R16+(R16*(R17-1)))*(R19-1)+R16+(R16*(R17-1))+((R16*(R17-1))+R16)*(R18-1))/R16))) -> 0 | S30: =MAX(0,((S11*$L$30-S11)*(((((S16*(S17-1))+S16)*(S18-1)+S16+(S16*(S17-1)))*(S19-1)+S16+(S16*(S17-1))+((S16*(S17-1))+S16)*(S18-1))/S16))) -> 0 | T30: =MAX(0,((T11*$L$30-T11)*(((((T16*(T17-1))+T16)*(T18-1)+T16+(T16*(T17-1)))*(T19-1)+T16+(T16*(T17-1))+((T16*(T17-1))+T16)*(T18-1))/T16))) -> 0 | ... AD30: =MAX(0,((AD11*$L$30-AD11)*(((((AD16*(AD17-1))+AD16)*(AD18-1)+AD16+(AD16*(AD17-1)))*(AD19-1)+AD16+(AD16*(AD17-1))+((AD16*(AD17-1))+AD16)*(AD18-1))/AD16))) -> 0
B31: Grijswatersysteem | C31: =INPUT!E26 -> nee | D31: =IF(ISTEXT(C31), IF(ISNUMBER(SEARCH("nee",UPPER($C31))),"Optie A", IF(ISNUMBER(SEARCH("ja",UPPER($C31))),"Optie B",""))) -> Optie A | E31: W-installaties | F31: 0 | G31: 1.05 | L31: =IF(D31="","",INDEX($F31:$K31,MATCH(D31,{"Optie A";"Optie B";"Optie C";"Optie D";"Optie E";"Optie F"},0))) -> 0 | M31: =MAX(0,((M11*$L$31-M11)*(((((M16*(M17-1))+M16)*(M18-1)+M16+(M16*(M17-1)))*(M19-1)+M16+(M16*(M17-1))+((M16*(M17-1))+M16)*(M18-1))/M16))) -> 0 | N31: =MAX(0,((N11*$L$31-N11)*(((((N16*(N17-1))+N16)*(N18-1)+N16+(N16*(N17-1)))*(N19-1)+N16+(N16*(N17-1))+((N16*(N17-1))+N16)*(N18-1))/N16))) -> 0 | O31: =MAX(0,((O11*$L$31-O11)*(((((O16*(O17-1))+O16)*(O18-1)+O16+(O16*(O17-1)))*(O19-1)+O16+(O16*(O17-1))+((O16*(O17-1))+O16)*(O18-1))/O16))) -> 0 | P31: =MAX(0,((P11*$L$31-P11)*(((((P16*(P17-1))+P16)*(P18-1)+P16+(P16*(P17-1)))*(P19-1)+P16+(P16*(P17-1))+((P16*(P17-1))+P16)*(P18-1))/P16))) -> 0 | Q31: =MAX(0,((Q11*$L$31-Q11)*(((((Q16*(Q17-1))+Q16)*(Q18-1)+Q16+(Q16*(Q17-1)))*(Q19-1)+Q16+(Q16*(Q17-1))+((Q16*(Q17-1))+Q16)*(Q18-1))/Q16))) -> 0 | R31: =MAX(0,((R11*$L$31-R11)*(((((R16*(R17-1))+R16)*(R18-1)+R16+(R16*(R17-1)))*(R19-1)+R16+(R16*(R17-1))+((R16*(R17-1))+R16)*(R18-1))/R16))) -> 0 | S31: =MAX(0,((S11*$L$31-S11)*(((((S16*(S17-1))+S16)*(S18-1)+S16+(S16*(S17-1)))*(S19-1)+S16+(S16*(S17-1))+((S16*(S17-1))+S16)*(S18-1))/S16))) -> 0 | T31: =MAX(0,((T11*$L$31-T11)*(((((T16*(T17-1))+T16)*(T18-1)+T16+(T16*(T17-1)))*(T19-1)+T16+(T16*(T17-1))+((T16*(T17-1))+T16)*(T18-1))/T16))) -> 0 | ... AD31: =MAX(0,((AD11*$L$31-AD11)*(((((AD16*(AD17-1))+AD16)*(AD18-1)+AD16+(AD16*(AD17-1)))*(AD19-1)+AD16+(AD16*(AD17-1))+((AD16*(AD17-1))+AD16)*(AD18-1))/AD16))) -> 0
B32: Groendak | C32: =INPUT!E27 -> nee | D32: =IF(ISTEXT(C32), IF(ISNUMBER(SEARCH("nee",UPPER($C32))),"Optie A", IF(ISNUMBER(SEARCH("ja",UPPER($C32))),"Optie B",""))) -> Optie A | E32: Dak, W-installaties | F32: 0 | G32: 1.075 | L32: =IF(D32="","",INDEX($F32:$K32,MATCH(D32,{"Optie A";"Optie B";"Optie C";"Optie D";"Optie E";"Optie F"},0))) -> 0 | M32: =MAX(0,((SUM(M11,M9)*$L$32-SUM(M11,M9))*(((((M16*(M17-1))+M16)*(M18-1)+M16+(M16*(M17-1)))*(M19-1)+M16+(M16*(M17-1))+((M16*(M17-1))+M16)*(M18-1))/M16))) -> 0 | N32: =MAX(0,((SUM(N11,N9)*$L$32-SUM(N11,N9))*(((((N16*(N17-1))+N16)*(N18-1)+N16+(N16*(N17-1)))*(N19-1)+N16+(N16*(N17-1))+((N16*(N17-1))+N16)*(N18-1))/N16))) -> 0 | O32: =MAX(0,((SUM(O11,O9)*$L$32-SUM(O11,O9))*(((((O16*(O17-1))+O16)*(O18-1)+O16+(O16*(O17-1)))*(O19-1)+O16+(O16*(O17-1))+((O16*(O17-1))+O16)*(O18-1))/O16))) -> 0 | P32: =MAX(0,((SUM(P11,P9)*$L$32-SUM(P11,P9))*(((((P16*(P17-1))+P16)*(P18-1)+P16+(P16*(P17-1)))*(P19-1)+P16+(P16*(P17-1))+((P16*(P17-1))+P16)*(P18-1))/P16))) -> 0 | Q32: =MAX(0,((SUM(Q11,Q9)*$L$32-SUM(Q11,Q9))*(((((Q16*(Q17-1))+Q16)*(Q18-1)+Q16+(Q16*(Q17-1)))*(Q19-1)+Q16+(Q16*(Q17-1))+((Q16*(Q17-1))+Q16)*(Q18-1))/Q16))) -> 0 | R32: =MAX(0,((SUM(R11,R9)*$L$32-SUM(R11,R9))*(((((R16*(R17-1))+R16)*(R18-1)+R16+(R16*(R17-1)))*(R19-1)+R16+(R16*(R17-1))+((R16*(R17-1))+R16)*(R18-1))/R16))) -> 0 | S32: =MAX(0,((SUM(S11,S9)*$L$32-SUM(S11,S9))*(((((S16*(S17-1))+S16)*(S18-1)+S16+(S16*(S17-1)))*(S19-1)+S16+(S16*(S17-1))+((S16*(S17-1))+S16)*(S18-1))/S16))) -> 0 | T32: =MAX(0,((SUM(T11,T9)*$L$32-SUM(T11,T9))*(((((T16*(T17-1))+T16)*(T18-1)+T16+(T16*(T17-1)))*(T19-1)+T16+(T16*(T17-1))+((T16*(T17-1))+T16)*(T18-1))/T16))) -> 0 | ... AD32: =MAX(0,((SUM(AD11,AD9)*$L$32-SUM(AD11,AD9))*(((((AD16*(AD17-1))+AD16)*(AD18-1)+AD16+(AD16*(AD17-1)))*(AD19-1)+AD16+(AD16*(AD17-1))+((AD16*(AD17-1))+AD16)*(AD18-1))/AD16))) -> 0
B33: Waterretentie systeem | C33: =INPUT!E28 -> nee | D33: =IF(ISTEXT(C33), IF(ISNUMBER(SEARCH("nee",UPPER($C33))),"Optie A", IF(ISNUMBER(SEARCH("ja",UPPER($C33))),"Optie B",""))) -> Optie A | E33: Dak, W-installaties, Terrein | F33: 0 | G33: 1.02 | L33: =IF(D33="","",INDEX($F33:$K33,MATCH(D33,{"Optie A";"Optie B";"Optie C";"Optie D";"Optie E";"Optie F"},0))) -> 0 | M33: =MAX(0,((SUM(M9,M11,M15)*$L$33-SUM(M9,M11,M15))*(((((M16*(M17-1))+M16)*(M18-1)+M16+(M16*(M17-1)))*(M19-1)+M16+(M16*(M17-1))+((M16*(M17-1))+M16)*(M18-1))/M16))) -> 0 | N33: =MAX(0,((SUM(N9,N11,N15)*$L$33-SUM(N9,N11,N15))*(((((N16*(N17-1))+N16)*(N18-1)+N16+(N16*(N17-1)))*(N19-1)+N16+(N16*(N17-1))+((N16*(N17-1))+N16)*(N18-1))/N16))) -> 0 | O33: =MAX(0,((SUM(O9,O11,O15)*$L$33-SUM(O9,O11,O15))*(((((O16*(O17-1))+O16)*(O18-1)+O16+(O16*(O17-1)))*(O19-1)+O16+(O16*(O17-1))+((O16*(O17-1))+O16)*(O18-1))/O16))) -> 0 | P33: =MAX(0,((SUM(P9,P11,P15)*$L$33-SUM(P9,P11,P15))*(((((P16*(P17-1))+P16)*(P18-1)+P16+(P16*(P17-1)))*(P19-1)+P16+(P16*(P17-1))+((P16*(P17-1))+P16)*(P18-1))/P16))) -> 0 | Q33: =MAX(0,((SUM(Q9,Q11,Q15)*$L$33-SUM(Q9,Q11,Q15))*(((((Q16*(Q17-1))+Q16)*(Q18-1)+Q16+(Q16*(Q17-1)))*(Q19-1)+Q16+(Q16*(Q17-1))+((Q16*(Q17-1))+Q16)*(Q18-1))/Q16))) -> 0 | R33: =MAX(0,((SUM(R9,R11,R15)*$L$33-SUM(R9,R11,R15))*(((((R16*(R17-1))+R16)*(R18-1)+R16+(R16*(R17-1)))*(R19-1)+R16+(R16*(R17-1))+((R16*(R17-1))+R16)*(R18-1))/R16))) -> 0 | S33: =MAX(0,((SUM(S9,S11,S15)*$L$33-SUM(S9,S11,S15))*(((((S16*(S17-1))+S16)*(S18-1)+S16+(S16*(S17-1)))*(S19-1)+S16+(S16*(S17-1))+((S16*(S17-1))+S16)*(S18-1))/S16))) -> 0 | T33: =MAX(0,((SUM(T9,T11,T15)*$L$33-SUM(T9,T11,T15))*(((((T16*(T17-1))+T16)*(T18-1)+T16+(T16*(T17-1)))*(T19-1)+T16+(T16*(T17-1))+((T16*(T17-1))+T16)*(T18-1))/T16))) -> 0 | ... AD33: =MAX(0,((SUM(AD9,AD11,AD15)*$L$33-SUM(AD9,AD11,AD15))*(((((AD16*(AD17-1))+AD16)*(AD18-1)+AD16+(AD16*(AD17-1)))*(AD19-1)+AD16+(AD16*(AD17-1))+((AD16*(AD17-1))+AD16)*(AD18-1))/AD16))) -> 0
B34: Extra beveiligingsmaatregelen | C34: =INPUT!E29 -> nee | D34: =IF(ISTEXT(C34), IF(ISNUMBER(SEARCH("nee",UPPER($C34))),"Optie A", IF(ISNUMBER(SEARCH("ja",UPPER($C34))),"Optie B",""))) -> Optie A | E34: E-installaties | F34: 0 | G34: 1.02 | L34: =IF(D34="","",INDEX($F34:$K34,MATCH(D34,{"Optie A";"Optie B";"Optie C";"Optie D";"Optie E";"Optie F"},0))) -> 0 | M34: =MAX(0,((M12*$L$34-M12)*(((((M16*(M17-1))+M16)*(M18-1)+M16+(M16*(M17-1)))*(M19-1)+M16+(M16*(M17-1))+((M16*(M17-1))+M16)*(M18-1))/M16))) -> 0 | N34: =MAX(0,((N12*$L$34-N12)*(((((N16*(N17-1))+N16)*(N18-1)+N16+(N16*(N17-1)))*(N19-1)+N16+(N16*(N17-1))+((N16*(N17-1))+N16)*(N18-1))/N16))) -> 0 | O34: =MAX(0,((O12*$L$34-O12)*(((((O16*(O17-1))+O16)*(O18-1)+O16+(O16*(O17-1)))*(O19-1)+O16+(O16*(O17-1))+((O16*(O17-1))+O16)*(O18-1))/O16))) -> 0 | P34: =MAX(0,((P12*$L$34-P12)*(((((P16*(P17-1))+P16)*(P18-1)+P16+(P16*(P17-1)))*(P19-1)+P16+(P16*(P17-1))+((P16*(P17-1))+P16)*(P18-1))/P16))) -> 0 | Q34: =MAX(0,((Q12*$L$34-Q12)*(((((Q16*(Q17-1))+Q16)*(Q18-1)+Q16+(Q16*(Q17-1)))*(Q19-1)+Q16+(Q16*(Q17-1))+((Q16*(Q17-1))+Q16)*(Q18-1))/Q16))) -> 0 | R34: =MAX(0,((R12*$L$34-R12)*(((((R16*(R17-1))+R16)*(R18-1)+R16+(R16*(R17-1)))*(R19-1)+R16+(R16*(R17-1))+((R16*(R17-1))+R16)*(R18-1))/R16))) -> 0 | S34: =MAX(0,((S12*$L$34-S12)*(((((S16*(S17-1))+S16)*(S18-1)+S16+(S16*(S17-1)))*(S19-1)+S16+(S16*(S17-1))+((S16*(S17-1))+S16)*(S18-1))/S16))) -> 0 | T34: =MAX(0,((T12*$L$34-T12)*(((((T16*(T17-1))+T16)*(T18-1)+T16+(T16*(T17-1)))*(T19-1)+T16+(T16*(T17-1))+((T16*(T17-1))+T16)*(T18-1))/T16))) -> 0 | ... AD34: =MAX(0,((AD12*$L$34-AD12)*(((((AD16*(AD17-1))+AD16)*(AD18-1)+AD16+(AD16*(AD17-1)))*(AD19-1)+AD16+(AD16*(AD17-1))+((AD16*(AD17-1))+AD16)*(AD18-1))/AD16))) -> 0
